Workbook

Sheet 결과
A1: 결과 요약 — batch 1
A2: 경량화 설정 | B2: =설정!$B$70 -> Attn W4 / GDN W4 / FFN W4 / Router W8 / LM W4 / A8 / KV8 / state 32b / top-k CPU
A3: HW | B3: =설정!$B$5&" GB/s (실효 "&TEXT(설정!$B$6,"0%")&"), SRAM "&설정!$B$9&" MB, 연산 실효율 "&TEXT(설정!$B$7,"0%") -> 68 GB/s (실효 75%), SRAM 4 MB, 연산 실효율 60%
A4: 디코드 컨텍스트 | B4: ="입력 + "&설정!$B$51*설정!$B$52&" 토큰 시점 기준" -> 입력 + 128 토큰 시점 기준
A5: 모델용 DRAM (GiB) | B5: =설정!$B$62 -> 13 | C5: ="(DRAM "&설정!$B$11&" GiB − 예약 "&설정!$B$12&" GiB)" -> (DRAM 16 GiB − 예약 3 GiB)
A6: 모델 요약
A7: 항목 | B7: =모델!B6 -> Llama 3.1 8B Instruct | D7: =모델!C6 -> gpt-oss-20b | F7: =모델!D6 -> Qwen3.6-35B-A3B | H7: =모델!E6 -> Gemma 4 26B-A4B | J7: =모델!F6 -> Llama 3.2 3B Instruct
A8: 총 파라미터 (B) | B8: =모델!$B$59 -> 8.029995 | D8: =모델!$C$59 -> 20.907786 | F8: =모델!$D$59 -> 34.659369 | H8: =모델!$E$59 -> 25.232441 | J8: =모델!$F$59 -> 3.2125747
A9: 토큰당 활성 파라미터 (B) | B9: =모델!$B$60 -> 7.5046584 | D9: =모델!$C$60 -> 3.6071424 | F9: =모델!$D$60 -> 2.9451878 | H9: =모델!$E$60 -> 3.8218301 | J9: =모델!$F$60 -> 3.2125747
A10: 경량화 후 가중치 (GB) | B10: =모델!$B$61 -> 4.1404662 | D10: =모델!$C$61 -> 10.781683 | F10: =모델!$D$61 -> 17.881723 | H10: =모델!$E$61 -> 13.015884 | J10: =모델!$F$61 -> 1.6564838
A11: KV/state 캐시 @ 최대 길이 (MB) | B11: =모델!$B$62 -> 512 | D11: =모델!$C$62 -> 97.5 | F11: =모델!$D$62 -> 140.70312 | H11: =모델!$E$62 -> 180 | J11: =모델!$F$62 -> 448
A12: DRAM 체크 @ 최대 입력+출력 (여유+ / 부족− GiB) | B12: =계산_모델1!H211 -> OK +8.1 | D12: =계산_모델2!H211 -> OK +2.4 | F12: =계산_모델3!H211 -> 초과 -4.3 | H12: =계산_모델4!H211 -> OK +0.2 | J12: =계산_모델5!H211 -> OK +10.5
A14: TTFT / 디코드 속도
B15: =모델!B6 -> Llama 3.1 8B Instruct | D15: =모델!C6 -> gpt-oss-20b | F15: =모델!D6 -> Qwen3.6-35B-A3B | H15: =모델!E6 -> Gemma 4 26B-A4B | J15: =모델!F6 -> Llama 3.2 3B Instruct
A16: 입력 길이 | B16: TTFT (ms) | C16: tok/s | D16: TTFT (ms) | E16: tok/s | F16: TTFT (ms) | G16: tok/s | H16: TTFT (ms) | I16: tok/s | J16: TTFT (ms) | K16: tok/s
A17: =설정!$B$54 -> 128 | B17: =계산_모델1!B111 -> 112.50398 | C17: =계산_모델1!B192 -> 11.920564 | D17: =계산_모델2!B111 -> 235.49075 | E17: =계산_모델2!B192 -> 23.419076 | F17: =계산_모델3!B111 -> 393.94258 | G17: =계산_모델3!B192 -> 25.060811 | H17: =계산_모델4!B111 -> 296.32485 | I17: =계산_모델4!B192 -> 21.577539 | J17: =계산_모델5!B111 -> 40.559505 | K17: =계산_모델5!B192 -> 27.71309
A18: =설정!$C$54 -> 256 | B18: =계산_모델1!C111 -> 193.29028 | C18: =계산_모델1!C192 -> 11.894909 | D18: =계산_모델2!C111 -> 247.61317 | E18: =계산_모델2!C192 -> 23.400485 | F18: =계산_모델3!C111 -> 426.25475 | G18: =계산_모델3!C192 -> 25.043068 | H18: =계산_모델4!C111 -> 323.10294 | I18: =계산_모델4!C192 -> 21.433717 | J18: =계산_모델5!C111 -> 72.672634 | K18: =계산_모델5!C192 -> 27.592033
A19: =설정!$D$54 -> 512 | B19: =계산_모델1!D111 -> 359.83777 | C19: =계산_모델1!D192 -> 11.84393 | D19: =계산_모델2!D111 -> 273.75054 | E19: =계산_모델2!D192 -> 23.363391 | F19: =계산_모델3!D111 -> 483.98049 | G19: =계산_모델3!D192 -> 25.007659 | H19: =계산_모델4!D111 -> 380.5526 | I19: =계산_모델4!D192 -> 21.15175 | J19: =계산_모델5!D111 -> 139.20268 | K19: =계산_모델5!D192 -> 27.353065
A20: =설정!$E$54 -> 1024 | B20: =계산_모델1!E111 -> 698.3064 | C20: =계산_모델1!E192 -> 11.743269 | D20: =계산_모델2!E111 -> 328.3622 | E20: =계산_모델2!E192 -> 23.289554 | F20: =계산_모델3!E111 -> 601.45918 | G20: =계산_모델3!E192 -> 24.937139 | H20: =계산_모델4!E111 -> 500.41086 | I20: =계산_모델4!E192 -> 20.730284 | J20: =계산_모델5!E111 -> 277.23053 | K20: =계산_모델5!E192 -> 26.887335
A21: =설정!$F$54 -> 2048 | B21: =계산_모델1!F111 -> 1415.9646 | C21: =계산_모델1!F192 -> 11.546997 | D21: =계산_모델2!F111 -> 607.39417 | E21: =계산_모델2!F192 -> 23.143273 | F21: =계산_모델3!F111 -> 842.38518 | G21: =계산_모델3!F192 -> 24.797285 | H21: =계산_모델4!F111 -> 753.0879 | I21: =계산_모델4!F192 -> 20.633545 | J21: =계산_모델5!F111 -> 566.61203 | K21: =계산_모델5!F192 -> 26.001887
A22: =설정!$G$54 -> 4096 | B22: =계산_모델1!G111 -> 2905.975 | C22: =계산_모델1!G192 -> 11.173497 | D22: =계산_모델2!G111 -> 1243.6905 | E22: =계산_모델2!G192 -> 22.856154 | F22: =계산_모델3!G111 -> 1347.8595 | G22: =계산_모델3!G192 -> 24.522232 | H22: =계산_모델4!G111 -> 1340.1053 | I22: =계산_모델4!G192 -> 20.44275 | J22: =계산_모델5!G111 -> 1194.9819 | K22: =계산_모델5!G192 -> 24.395136
A23: =설정!$H$54 -> 8192 | B23: =계산_모델1!H111 -> 6209.2591 | C23: =계산_모델1!H192 -> 10.49458 | D23: =계산_모델2!H111 -> 2629.6702 | E23: =계산_모델2!H192 -> 22.302771 | F23: =계산_모델3!H111 -> 2453.2974 | G23: =계산_모델3!H192 -> 23.990034 | H23: =계산_모델4!H111 -> 2804.5769 | I23: =계산_모델4!H192 -> 20.071555 | J23: =계산_모델5!H111 -> 2650.1491 | K23: =계산_모델5!H192 -> 21.711831
A24: TTFT = 프롬프트 전체 프리필 + 첫 토큰 LM head (top-k 오버헤드 포함). tok/s = 위 컨텍스트 시점의 디코드 속도.
A26: MoE top-k 오버헤드 (Dense 모델은 0)
B27: =모델!B6 -> Llama 3.1 8B Instruct | D27: =모델!C6 -> gpt-oss-20b | F27: =모델!D6 -> Qwen3.6-35B-A3B | H27: =모델!E6 -> Gemma 4 26B-A4B | J27: =모델!F6 -> Llama 3.2 3B Instruct
A28: 입력 길이 | B28: TTFT 중 (ms) | C28: 토큰당 (ms) | D28: TTFT 중 (ms) | E28: 토큰당 (ms) | F28: TTFT 중 (ms) | G28: 토큰당 (ms) | H28: TTFT 중 (ms) | I28: 토큰당 (ms) | J28: TTFT 중 (ms) | K28: 토큰당 (ms)
A29: =설정!$B$54 -> 128 | B29: =계산_모델1!B104 -> 0 | C29: =계산_모델1!B187 -> 0 | D29: =계산_모델2!B104 -> 2.6236416 | E29: =계산_모델2!B187 -> 2.4017472 | F29: =계산_모델3!B104 -> 6.90816 | G29: =계산_모델3!B187 -> 4.02272 | H29: =계산_모델4!B104 -> 4.099776 | I29: =계산_모델4!B187 -> 3.008592 | J29: =계산_모델5!B104 -> 0 | K29: =계산_모델5!B187 -> 0
A30: =설정!$C$54 -> 256 | B30: =계산_모델1!C104 -> 0 | C30: =계산_모델1!C187 -> 0 | D30: =계산_모델2!C104 -> 2.8472832 | E30: =계산_모델2!C187 -> 2.4017472 | F30: =계산_모델3!C104 -> 9.81632 | G30: =계산_모델3!C187 -> 4.02272 | H30: =계산_모델4!C104 -> 5.199552 | I30: =계산_모델4!C187 -> 3.008592 | J30: =계산_모델5!C104 -> 0 | K30: =계산_모델5!C187 -> 0
A31: =설정!$D$54 -> 512 | B31: =계산_모델1!D104 -> 0 | C31: =계산_모델1!D187 -> 0 | D31: =계산_모델2!D104 -> 3.2945664 | E31: =계산_모델2!D187 -> 2.4017472 | F31: =계산_모델3!D104 -> 15.63264 | G31: =계산_모델3!D187 -> 4.02272 | H31: =계산_모델4!D104 -> 7.399104 | I31: =계산_모델4!D187 -> 3.008592 | J31: =계산_모델5!D104 -> 0 | K31: =계산_모델5!D187 -> 0
A32: =설정!$E$54 -> 1024 | B32: =계산_모델1!E104 -> 0 | C32: =계산_모델1!E187 -> 0 | D32: =계산_모델2!E104 -> 4.1891328 | E32: =계산_모델2!E187 -> 2.4017472 | F32: =계산_모델3!E104 -> 27.26528 | G32: =계산_모델3!E187 -> 4.02272 | H32: =계산_모델4!E104 -> 11.798208 | I32: =계산_모델4!E187 -> 3.008592 | J32: =계산_모델5!E104 -> 0 | K32: =계산_모델5!E187 -> 0
A33: =설정!$F$54 -> 2048 | B33: =계산_모델1!F104 -> 0 | C33: =계산_모델1!F187 -> 0 | D33: =계산_모델2!F104 -> 5.9782656 | E33: =계산_모델2!F187 -> 2.4017472 | F33: =계산_모델3!F104 -> 50.53056 | G33: =계산_모델3!F187 -> 4.02272 | H33: =계산_모델4!F104 -> 20.596416 | I33: =계산_모델4!F187 -> 3.008592 | J33: =계산_모델5!F104 -> 0 | K33: =계산_모델5!F187 -> 0
A34: =설정!$G$54 -> 4096 | B34: =계산_모델1!G104 -> 0 | C34: =계산_모델1!G187 -> 0 | D34: =계산_모델2!G104 -> 9.5565312 | E34: =계산_모델2!G187 -> 2.4017472 | F34: =계산_모델3!G104 -> 97.06112 | G34: =계산_모델3!G187 -> 4.02272 | H34: =계산_모델4!G104 -> 38.192832 | I34: =계산_모델4!G187 -> 3.008592 | J34: =계산_모델5!G104 -> 0 | K34: =계산_모델5!G187 -> 0
A35: =설정!$H$54 -> 8192 | B35: =계산_모델1!H104 -> 0 | C35: =계산_모델1!H187 -> 0 | D35: =계산_모델2!H104 -> 16.713062 | E35: =계산_모델2!H187 -> 2.4017472 | F35: =계산_모델3!H104 -> 190.12224 | G35: =계산_모델3!H187 -> 4.02272 | H35: =계산_모델4!H104 -> 73.385664 | I35: =계산_모델4!H187 -> 3.008592 | J35: =계산_모델5!H104 -> 0 | K35: =계산_모델5!H187 -> 0
A37: Gated DeltaNet 코어 시간 (GDN 없는 모델은 0, 오버헤드 비율 적용 전)
B38: =모델!B6 -> Llama 3.1 8B Instruct | D38: =모델!C6 -> gpt-oss-20b | F38: =모델!D6 -> Qwen3.6-35B-A3B | H38: =모델!E6 -> Gemma 4 26B-A4B | J38: =모델!F6 -> Llama 3.2 3B Instruct
A39: 입력 길이 | B39: 프리필 (ms) | C39: 토큰당 (ms) | D39: 프리필 (ms) | E39: 토큰당 (ms) | F39: 프리필 (ms) | G39: 토큰당 (ms) | H39: 프리필 (ms) | I39: 토큰당 (ms) | J39: 프리필 (ms) | K39: 토큰당 (ms)
A40: =설정!$B$54 -> 128 | B40: =계산_모델1!B103 -> 0 | C40: =계산_모델1!B186 -> 0 | D40: =계산_모델2!B103 -> 0 | E40: =계산_모델2!B186 -> 0 | F40: =계산_모델3!B103 -> 2.1636518 | G40: =계산_모델3!B186 -> 2.5034165 | H40: =계산_모델4!B103 -> 0 | I40: =계산_모델4!B186 -> 0 | J40: =계산_모델5!B103 -> 0 | K40: =계산_모델5!B186 -> 0
A41: =설정!$C$54 -> 256 | B41: =계산_모델1!C103 -> 0 | C41: =계산_모델1!C186 -> 0 | D41: =계산_모델2!C103 -> 0 | E41: =계산_모델2!C186 -> 0 | F41: =계산_모델3!C103 -> 3.6909875 | G41: =계산_모델3!C186 -> 2.5034165 | H41: =계산_모델4!C103 -> 0 | I41: =계산_모델4!C186 -> 0 | J41: =계산_모델5!C103 -> 0 | K41: =계산_모델5!C186 -> 0
A42: =설정!$D$54 -> 512 | B42: =계산_모델1!D103 -> 0 | C42: =계산_모델1!D186 -> 0 | D42: =계산_모델2!D103 -> 0 | E42: =계산_모델2!D186 -> 0 | F42: =계산_모델3!D103 -> 7.381975 | G42: =계산_모델3!D186 -> 2.5034165 | H42: =계산_모델4!D103 -> 0 | I42: =계산_모델4!D186 -> 0 | J42: =계산_모델5!D103 -> 0 | K42: =계산_모델5!D186 -> 0
A43: =설정!$E$54 -> 1024 | B43: =계산_모델1!E103 -> 0 | C43: =계산_모델1!E186 -> 0 | D43: =계산_모델2!E103 -> 0 | E43: =계산_모델2!E186 -> 0 | F43: =계산_모델3!E103 -> 14.76395 | G43: =계산_모델3!E186 -> 2.5034165 | H43: =계산_모델4!E103 -> 0 | I43: =계산_모델4!E186 -> 0 | J43: =계산_모델5!E103 -> 0 | K43: =계산_모델5!E186 -> 0
...

Sheet 설정
A1: LLM NPU 성능 예측 계산기 — 설정
A2: 노란 칸(파란 글씨)이 입력값입니다. 들어 있는 숫자는 계산이 돌아가도록 넣은 예시값이니 실제 NPU/경량화 값으로 바꿔 주세요.
A4: 하드웨어 (NPU) — 직접 입력
A5: DRAM 대역폭 | B5: 68 | C5: GB/s | D5: 예시값
A6: 대역폭 실효율 | B6: 0.75 | D6: 피크 대비 실제 활용 비율
A7: 연산 실효율 | B7: 0.6 | D7: 피크 TOPS 대비 실제 활용 비율 (아래 모든 TOPS에 적용)
A8: Gated DeltaNet 코어 피크 TOPS | B8: 20 | C8: TOPS | D8: linear attention 코어(chunk 행렬곱, state 갱신). fp16 MAC 또는 vector unit 성능을 입력
A9: On-chip SRAM | B9: 4 | C9: MB
A10: SRAM 중 타일링 가용 비율 | B10: 0.8 | D10: 가용분을 입력 타일/가중치 타일에 반씩 배분
A11: DRAM 용량 | B11: 16 | C11: GiB | D11: 제품 표기 용량 (1 GiB = 2^30 B). 예시값
A12: OS/런타임 예약 용량 | B12: 3 | C12: GiB | D12: OS, 다른 앱, NPU 런타임, 펌웨어 등이 쓰는 몫
A13: 작업 버퍼 (activation, 임시 텐서) | B13: 0.5 | C13: GiB | D13: 모델 실행 중 중간 결과용
A14: 기타 연산 오버헤드 | B14: 0.1 | D14: Norm, RoPE, softmax, 활성화 함수, residual, conv1d 등. 선형층+어텐션 시간에 곱해짐
A15: 프리필 고정 지연 | B15: 0 | C15: ms | D15: 런타임/디스패치 등
A16: 디코드 토큰당 고정 지연 | B16: 0 | C16: ms
A18: 피크 TOPS 표 (Weight bit × Activation bit) | D18: 1 MAC = 2 ops 기준. 어텐션(QK·PV)은 KV bit를 Weight bit 자리에 넣어 조회
A19: Weight bit ＼ Activation bit | B19: 8 | C19: 16
A20: 4 | B20: 40 | C20: 20
A21: 8 | B21: 40 | C21: 20
A22: 16 | B22: 20 | C22: 20
A23: 표에 없는 bit는 그보다 작은 값 중 가장 가까운 행/열을 사용합니다 (예: W6 → W4 행).
A25: 경량화 — 직접 입력
A26: 구분 | B26: Weight bit | C26: Group 크기 | D26: Scale bit | E26: 적용 대상 / 설명
A27: Attention | B27: 4 | C27: 128 | D27: 16 | E27: full/sliding attention의 q/k/v/o_proj
A28: Linear attn (GDN) | B28: 4 | C28: 128 | D28: 16 | E28: Gated DeltaNet의 in_proj_qkv/z/a/b, out_proj
A29: FFN / Expert | B29: 4 | C29: 128 | D29: 16 | E29: dense MLP, shared expert, routed expert의 gate/up/down
A30: Router (MoE) | B30: 8 | C30: 128 | D30: 16 | E30: MoE gate. Dense 모델에는 영향 없음
A31: LM head | B31: 4 | C31: 128 | D31: 16 | E31: 출력 projection
A32: Embedding | B32: 4 | C32: 128 | D32: 16 | E32: lookup만 하므로 저장 용량에만 반영
A33: Group 크기 0 = per-channel (출력 채널마다 scale 1개). Weight bit 16 = 경량화 안 함 (scale 무시하려면 Scale bit 0).
A35: Activation bit | B35: 8 | C35: bit | D35: 8 또는 16
A36: KV cache bit | B36: 8 | C36: bit
A37: GDN recurrent state bit | B37: 32 | C37: bit | D37: Qwen3.6 config의 mamba_ssm_dtype = float32. fp16로 유지하면 16
A39: MoE top-k 처리 — 직접 입력 (Dense 모델에는 영향 없음)
A40: Top-k 실행 위치 | B40: CPU | D40: CPU = NPU에서 router logit을 CPU로 보냈다가 결과를 받아옴 / NPU = NPU 내부 처리
A41: NPU→CPU→NPU 왕복 고정 지연 | B41: 100 | C41: µs | D41: MoE layer당 1회. 동기화, 캐시 flush/invalidate, 인터럽트, 다음 연산 재개 비용
A42: NPU↔CPU 데이터 전송 대역폭 | B42: 10 | C42: GB/s | D42: 공유 DRAM이면 실효 복사 속도, PCIe면 링크 속도
A43: Router logit 전송 bit | B43: 16 | C43: bit | D43: NPU→CPU로 보내는 logit 정밀도
A44: 반환 데이터 (토큰×선택 expert당) | B44: 6 | C44: B | D44: 예: expert index int32 4B + routing weight fp16 2B
A45: CPU top-k+softmax 처리 시간 | B45: 2 | C45: ns/logit | D45: logit 하나(토큰×expert)당 CPU 처리 시간
...

Sheet 모델
A1: 모델 파라미터 (Hugging Face config.json 기준, 텍스트 모델만)
A2: 노란 칸 수정 가능. 사용하지 않는 블록은 layer 수를 0으로 두면 됩니다. 모델 5 칸은 사용자 정의용 (예시: Llama 3.2 3B Instruct).
A4: 항목 | B4: 모델 1 | C4: 모델 2 | D4: 모델 3 | E4: 모델 4 | F4: 모델 5 | G4: HF config 키 / 설명
A5: 공통
A6: 모델 이름 | B6: Llama 3.1 8B Instruct | C6: gpt-oss-20b | D6: Qwen3.6-35B-A3B | E6: Gemma 4 26B-A4B | F6: Llama 3.2 3B Instruct
A7: 전체 Layer 수 | B7: 32 | C7: 24 | D7: 40 | E7: 30 | F7: 28 | G7: num_hidden_layers
A8: Hidden 크기 | B8: 4096 | C8: 2880 | D8: 2048 | E8: 2816 | F8: 3072 | G8: hidden_size
A9: Vocab 크기 | B9: 128256 | C9: 201088 | D9: 248320 | E9: 262144 | F9: 128256 | G9: vocab_size
A10: 임베딩 공유 (1/0) | B10: 0 | C10: 0 | D10: 0 | E10: 1 | F10: 1 | G10: tie_word_embeddings
A11: Full (global) attention
A12: Layer 수 | B12: 32 | C12: 12 | D12: 10 | E12: 5 | F12: 28 | G12: layer_types 중 full_attention 개수
A13: Query head 수 | B13: 32 | C13: 64 | D13: 16 | E13: 16 | F13: 24 | G13: num_attention_heads
A14: KV head 수 | B14: 8 | C14: 8 | D14: 2 | E14: 2 | F14: 8 | G14: num_key_value_heads (Gemma 4: num_global_key_value_heads)
A15: Head 차원 | B15: 128 | C15: 64 | D15: 256 | E15: 512 | F15: 128 | G15: head_dim (Gemma 4: global_head_dim)
A16: q_proj 출력 배수 | B16: 1 | C16: 1 | D16: 2 | E16: 1 | F16: 1 | G16: Qwen3.6 attn_output_gate = 2 (query + gate), 그 외 1
A17: v_proj 존재 (1/0) | B17: 1 | C17: 1 | D17: 1 | E17: 0 | F17: 1 | G17: Gemma 4 global은 attention_k_eq_v → 0 (V=K, KV cache는 K/V 모두 저장으로 가정)
A18: Sliding window attention
A19: Layer 수 | B19: 0 | C19: 12 | D19: 0 | E19: 25 | F19: 0 | G19: layer_types 중 sliding_attention 개수
A20: Window 크기 | B20: 0 | C20: 128 | D20: 0 | E20: 1024 | F20: 0 | G20: sliding_window
A21: Query head 수 | B21: 0 | C21: 64 | D21: 0 | E21: 16 | F21: 0 | G21: num_attention_heads
A22: KV head 수 | B22: 0 | C22: 8 | D22: 0 | E22: 8 | F22: 0 | G22: num_key_value_heads
A23: Head 차원 | B23: 0 | C23: 64 | D23: 0 | E23: 256 | F23: 0 | G23: head_dim
A24: v_proj 존재 (1/0) | B24: 1 | C24: 1 | D24: 1 | E24: 1 | F24: 1
A25: Linear attention (Gated DeltaNet)
A26: Layer 수 | B26: 0 | C26: 0 | D26: 30 | E26: 0 | F26: 0 | G26: layer_types 중 linear_attention 개수
A27: Key head 수 | B27: 0 | C27: 0 | D27: 16 | E27: 0 | F27: 0 | G27: linear_num_key_heads
A28: Key head 차원 | B28: 0 | C28: 0 | D28: 128 | E28: 0 | F28: 0 | G28: linear_key_head_dim
A29: Value head 수 | B29: 0 | C29: 0 | D29: 32 | E29: 0 | F29: 0 | G29: linear_num_value_heads
A30: Value head 차원 | B30: 0 | C30: 0 | D30: 128 | E30: 0 | F30: 0 | G30: linear_value_head_dim
A31: Conv kernel 크기 | B31: 0 | C31: 0 | D31: 4 | E31: 0 | F31: 0 | G31: linear_conv_kernel_dim
A32: Chunk 크기 (프리필) | B32: 64 | C32: 64 | D32: 64 | E32: 64 | F32: 64 | G32: transformers chunk_gated_delta_rule 기본값 64
A33: FFN / MoE
A34: 항상 활성 FFN intermediate | B34: 14336 | C34: 0 | D34: 512 | E34: 2112 | F34: 8192 | G34: Dense MLP intermediate_size, Qwen은 shared_expert_intermediate_size, Gemma 4는 MoE 옆 dense MLP. 없으면 0
A35: FFN 행렬 수 | B35: 3 | C35: 3 | D35: 3 | E35: 3 | F35: 3 | G35: SwiGLU/GeGLU = 3 (gate, up, down). 융합된 gate_up도 3으로 계산
A36: Routed expert 수 | B36: 0 | C36: 32 | D36: 256 | E36: 128 | F36: 0 | G36: num_local_experts / num_experts (Dense = 0)
A37: 토큰당 활성 expert 수 | B37: 0 | C37: 4 | D37: 8 | E37: 8 | F37: 0 | G37: num_experts_per_tok / top_k_experts (Dense = 0)
A38: Expert intermediate | B38: 0 | C38: 2880 | D38: 512 | E38: 704 | F38: 0 | G38: moe_intermediate_size (gpt-oss는 intermediate_size)
A39: 출처 (2026-10-01 확인, 구조는 transformers main 브랜치 modeling 코드로 교차 확인):
A40: Llama 3.1 8B Instruct: huggingface.co/meta-llama/Llama-3.1-8B-Instruct (gated, 공개 미러 unsloth/Llama-3.1-8B-Instruct의 동일 config로 확인)
A41: gpt-oss-20b: huggingface.co/openai/gpt-oss-20b
...

Sheet Expert 실측
A1: MoE 프리필 expert 사용 수 — 실측값 입력
A2: moe_routing_stats.py 결과의 excel_paste_<모델>.csv 중 measured_used_layer_avg 열을 해당 모델 칸에 붙여 넣으세요. '설정' 시트의 '프리필 expert 사용 수 기준'을 '실측'으로 바꾸면 적용됩니다. 빈 칸은 균등 공식으로 계산합니다.
A3: 현재 기준 | B3: =설정!$B$47 -> 균등
A5: ① 실측 사용 expert 수 (layer 평균, 도메인별 p95 중 최댓값) — 직접 입력
A6: 입력 길이 | B6: =모델!B6 -> Llama 3.1 8B Instruct | C6: =모델!C6 -> gpt-oss-20b | D6: =모델!D6 -> Qwen3.6-35B-A3B | E6: =모델!E6 -> Gemma 4 26B-A4B | F6: =모델!F6 -> Llama 3.2 3B Instruct
A7: =설정!$B$54 -> 128
A8: =설정!$C$54 -> 256
A9: =설정!$D$54 -> 512
A10: =설정!$E$54 -> 1024
A11: =설정!$F$54 -> 2048
A12: =설정!$G$54 -> 4096
A13: =설정!$H$54 -> 8192
A15: ② 균등 가정 사용 expert 수 (참고, 자동 계산)
A16: 입력 길이 | B16: =모델!B6 -> Llama 3.1 8B Instruct | C16: =모델!C6 -> gpt-oss-20b | D16: =모델!D6 -> Qwen3.6-35B-A3B | E16: =모델!E6 -> Gemma 4 26B-A4B | F16: =모델!F6 -> Llama 3.2 3B Instruct
A17: =설정!$B$54 -> 128 | B17: =IF(모델!$B$36>1,모델!$B$36*(1-EXP(MAX(-700,설정!$B$54*LN(1-MIN(모델!$B$37/모델!$B$36,0.999999))))),0) -> 0 | C17: =IF(모델!$C$36>1,모델!$C$36*(1-EXP(MAX(-700,설정!$B$54*LN(1-MIN(모델!$C$37/모델!$C$36,0.999999))))),0) -> 31.999999 | D17: =IF(모델!$D$36>1,모델!$D$36*(1-EXP(MAX(-700,설정!$B$54*LN(1-MIN(모델!$D$37/모델!$D$36,0.999999))))),0) -> 251.60115 | E17: =IF(모델!$E$36>1,모델!$E$36*(1-EXP(MAX(-700,설정!$B$54*LN(1-MIN(모델!$E$37/모델!$E$36,0.999999))))),0) -> 127.96692 | F17: =IF(모델!$F$36>1,모델!$F$36*(1-EXP(MAX(-700,설정!$B$54*LN(1-MIN(모델!$F$37/모델!$F$36,0.999999))))),0) -> 0
A18: =설정!$C$54 -> 256 | B18: =IF(모델!$B$36>1,모델!$B$36*(1-EXP(MAX(-700,설정!$C$54*LN(1-MIN(모델!$B$37/모델!$B$36,0.999999))))),0) -> 0 | C18: =IF(모델!$C$36>1,모델!$C$36*(1-EXP(MAX(-700,설정!$C$54*LN(1-MIN(모델!$C$37/모델!$C$36,0.999999))))),0) -> 32 | D18: =IF(모델!$D$36>1,모델!$D$36*(1-EXP(MAX(-700,설정!$C$54*LN(1-MIN(모델!$D$37/모델!$D$36,0.999999))))),0) -> 255.92441 | E18: =IF(모델!$E$36>1,모델!$E$36*(1-EXP(MAX(-700,설정!$C$54*LN(1-MIN(모델!$E$37/모델!$E$36,0.999999))))),0) -> 127.99999 | F18: =IF(모델!$F$36>1,모델!$F$36*(1-EXP(MAX(-700,설정!$C$54*LN(1-MIN(모델!$F$37/모델!$F$36,0.999999))))),0) -> 0
A19: =설정!$D$54 -> 512 | B19: =IF(모델!$B$36>1,모델!$B$36*(1-EXP(MAX(-700,설정!$D$54*LN(1-MIN(모델!$B$37/모델!$B$36,0.999999))))),0) -> 0 | C19: =IF(모델!$C$36>1,모델!$C$36*(1-EXP(MAX(-700,설정!$D$54*LN(1-MIN(모델!$C$37/모델!$C$36,0.999999))))),0) -> 32 | D19: =IF(모델!$D$36>1,모델!$D$36*(1-EXP(MAX(-700,설정!$D$54*LN(1-MIN(모델!$D$37/모델!$D$36,0.999999))))),0) -> 255.99998 | E19: =IF(모델!$E$36>1,모델!$E$36*(1-EXP(MAX(-700,설정!$D$54*LN(1-MIN(모델!$E$37/모델!$E$36,0.999999))))),0) -> 128 | F19: =IF(모델!$F$36>1,모델!$F$36*(1-EXP(MAX(-700,설정!$D$54*LN(1-MIN(모델!$F$37/모델!$F$36,0.999999))))),0) -> 0
A20: =설정!$E$54 -> 1024 | B20: =IF(모델!$B$36>1,모델!$B$36*(1-EXP(MAX(-700,설정!$E$54*LN(1-MIN(모델!$B$37/모델!$B$36,0.999999))))),0) -> 0 | C20: =IF(모델!$C$36>1,모델!$C$36*(1-EXP(MAX(-700,설정!$E$54*LN(1-MIN(모델!$C$37/모델!$C$36,0.999999))))),0) -> 32 | D20: =IF(모델!$D$36>1,모델!$D$36*(1-EXP(MAX(-700,설정!$E$54*LN(1-MIN(모델!$D$37/모델!$D$36,0.999999))))),0) -> 256 | E20: =IF(모델!$E$36>1,모델!$E$36*(1-EXP(MAX(-700,설정!$E$54*LN(1-MIN(모델!$E$37/모델!$E$36,0.999999))))),0) -> 128 | F20: =IF(모델!$F$36>1,모델!$F$36*(1-EXP(MAX(-700,설정!$E$54*LN(1-MIN(모델!$F$37/모델!$F$36,0.999999))))),0) -> 0
A21: =설정!$F$54 -> 2048 | B21: =IF(모델!$B$36>1,모델!$B$36*(1-EXP(MAX(-700,설정!$F$54*LN(1-MIN(모델!$B$37/모델!$B$36,0.999999))))),0) -> 0 | C21: =IF(모델!$C$36>1,모델!$C$36*(1-EXP(MAX(-700,설정!$F$54*LN(1-MIN(모델!$C$37/모델!$C$36,0.999999))))),0) -> 32 | D21: =IF(모델!$D$36>1,모델!$D$36*(1-EXP(MAX(-700,설정!$F$54*LN(1-MIN(모델!$D$37/모델!$D$36,0.999999))))),0) -> 256 | E21: =IF(모델!$E$36>1,모델!$E$36*(1-EXP(MAX(-700,설정!$F$54*LN(1-MIN(모델!$E$37/모델!$E$36,0.999999))))),0) -> 128 | F21: =IF(모델!$F$36>1,모델!$F$36*(1-EXP(MAX(-700,설정!$F$54*LN(1-MIN(모델!$F$37/모델!$F$36,0.999999))))),0) -> 0
A22: =설정!$G$54 -> 4096 | B22: =IF(모델!$B$36>1,모델!$B$36*(1-EXP(MAX(-700,설정!$G$54*LN(1-MIN(모델!$B$37/모델!$B$36,0.999999))))),0) -> 0 | C22: =IF(모델!$C$36>1,모델!$C$36*(1-EXP(MAX(-700,설정!$G$54*LN(1-MIN(모델!$C$37/모델!$C$36,0.999999))))),0) -> 32 | D22: =IF(모델!$D$36>1,모델!$D$36*(1-EXP(MAX(-700,설정!$G$54*LN(1-MIN(모델!$D$37/모델!$D$36,0.999999))))),0) -> 256 | E22: =IF(모델!$E$36>1,모델!$E$36*(1-EXP(MAX(-700,설정!$G$54*LN(1-MIN(모델!$E$37/모델!$E$36,0.999999))))),0) -> 128 | F22: =IF(모델!$F$36>1,모델!$F$36*(1-EXP(MAX(-700,설정!$G$54*LN(1-MIN(모델!$F$37/모델!$F$36,0.999999))))),0) -> 0
A23: =설정!$H$54 -> 8192 | B23: =IF(모델!$B$36>1,모델!$B$36*(1-EXP(MAX(-700,설정!$H$54*LN(1-MIN(모델!$B$37/모델!$B$36,0.999999))))),0) -> 0 | C23: =IF(모델!$C$36>1,모델!$C$36*(1-EXP(MAX(-700,설정!$H$54*LN(1-MIN(모델!$C$37/모델!$C$36,0.999999))))),0) -> 32 | D23: =IF(모델!$D$36>1,모델!$D$36*(1-EXP(MAX(-700,설정!$H$54*LN(1-MIN(모델!$D$37/모델!$D$36,0.999999))))),0) -> 256 | E23: =IF(모델!$E$36>1,모델!$E$36*(1-EXP(MAX(-700,설정!$H$54*LN(1-MIN(모델!$E$37/모델!$E$36,0.999999))))),0) -> 128 | F23: =IF(모델!$F$36>1,모델!$F$36*(1-EXP(MAX(-700,설정!$H$54*LN(1-MIN(모델!$F$37/모델!$F$36,0.999999))))),0) -> 0
A25: ③ 실제 계산에 적용되는 사용 비율 (자동 계산)
A26: 입력 길이 | B26: =모델!B6 -> Llama 3.1 8B Instruct | C26: =모델!C6 -> gpt-oss-20b | D26: =모델!D6 -> Qwen3.6-35B-A3B | E26: =모델!E6 -> Gemma 4 26B-A4B | F26: =모델!F6 -> Llama 3.2 3B Instruct
A27: =설정!$B$54 -> 128 | B27: =IF(모델!$B$36>1,IF(AND(설정!$B$47="실측",ISNUMBER('Expert 실측'!$B$7)),MIN(모델!$B$36,'Expert 실측'!$B$7),'Expert 실측'!$B$17)/모델!$B$36,"-") -> - | C27: =IF(모델!$C$36>1,IF(AND(설정!$B$47="실측",ISNUMBER('Expert 실측'!$C$7)),MIN(모델!$C$36,'Expert 실측'!$C$7),'Expert 실측'!$C$17)/모델!$C$36,"-") -> 0.99999996 | D27: =IF(모델!$D$36>1,IF(AND(설정!$B$47="실측",ISNUMBER('Expert 실측'!$D$7)),MIN(모델!$D$36,'Expert 실측'!$D$7),'Expert 실측'!$D$17)/모델!$D$36,"-") -> 0.98281698 | E27: =IF(모델!$E$36>1,IF(AND(설정!$B$47="실측",ISNUMBER('Expert 실측'!$E$7)),MIN(모델!$E$36,'Expert 실측'!$E$7),'Expert 실측'!$E$17)/모델!$E$36,"-") -> 0.99974158 | F27: =IF(모델!$F$36>1,IF(AND(설정!$B$47="실측",ISNUMBER('Expert 실측'!$F$7)),MIN(모델!$F$36,'Expert 실측'!$F$7),'Expert 실측'!$F$17)/모델!$F$36,"-") -> -
A28: =설정!$C$54 -> 256 | B28: =IF(모델!$B$36>1,IF(AND(설정!$B$47="실측",ISNUMBER('Expert 실측'!$B$8)),MIN(모델!$B$36,'Expert 실측'!$B$8),'Expert 실측'!$B$18)/모델!$B$36,"-") -> - | C28: =IF(모델!$C$36>1,IF(AND(설정!$B$47="실측",ISNUMBER('Expert 실측'!$C$8)),MIN(모델!$C$36,'Expert 실측'!$C$8),'Expert 실측'!$C$18)/모델!$C$36,"-") -> 1 | D28: =IF(모델!$D$36>1,IF(AND(설정!$B$47="실측",ISNUMBER('Expert 실측'!$D$8)),MIN(모델!$D$36,'Expert 실측'!$D$8),'Expert 실측'!$D$18)/모델!$D$36,"-") -> 0.99970474 | E28: =IF(모델!$E$36>1,IF(AND(설정!$B$47="실측",ISNUMBER('Expert 실측'!$E$8)),MIN(모델!$E$36,'Expert 실측'!$E$8),'Expert 실측'!$E$18)/모델!$E$36,"-") -> 0.99999993 | F28: =IF(모델!$F$36>1,IF(AND(설정!$B$47="실측",ISNUMBER('Expert 실측'!$F$8)),MIN(모델!$F$36,'Expert 실측'!$F$8),'Expert 실측'!$F$18)/모델!$F$36,"-") -> -
A29: =설정!$D$54 -> 512 | B29: =IF(모델!$B$36>1,IF(AND(설정!$B$47="실측",ISNUMBER('Expert 실측'!$B$9)),MIN(모델!$B$36,'Expert 실측'!$B$9),'Expert 실측'!$B$19)/모델!$B$36,"-") -> - | C29: =IF(모델!$C$36>1,IF(AND(설정!$B$47="실측",ISNUMBER('Expert 실측'!$C$9)),MIN(모델!$C$36,'Expert 실측'!$C$9),'Expert 실측'!$C$19)/모델!$C$36,"-") -> 1 | D29: =IF(모델!$D$36>1,IF(AND(설정!$B$47="실측",ISNUMBER('Expert 실측'!$D$9)),MIN(모델!$D$36,'Expert 실측'!$D$9),'Expert 실측'!$D$19)/모델!$D$36,"-") -> 0.99999991 | E29: =IF(모델!$E$36>1,IF(AND(설정!$B$47="실측",ISNUMBER('Expert 실측'!$E$9)),MIN(모델!$E$36,'Expert 실측'!$E$9),'Expert 실측'!$E$19)/모델!$E$36,"-") -> 1 | F29: =IF(모델!$F$36>1,IF(AND(설정!$B$47="실측",ISNUMBER('Expert 실측'!$F$9)),MIN(모델!$F$36,'Expert 실측'!$F$9),'Expert 실측'!$F$19)/모델!$F$36,"-") -> -
A30: =설정!$E$54 -> 1024 | B30: =IF(모델!$B$36>1,IF(AND(설정!$B$47="실측",ISNUMBER('Expert 실측'!$B$10)),MIN(모델!$B$36,'Expert 실측'!$B$10),'Expert 실측'!$B$20)/모델!$B$36,"-") -> - | C30: =IF(모델!$C$36>1,IF(AND(설정!$B$47="실측",ISNUMBER('Expert 실측'!$C$10)),MIN(모델!$C$36,'Expert 실측'!$C$10),'Expert 실측'!$C$20)/모델!$C$36,"-") -> 1 | D30: =IF(모델!$D$36>1,IF(AND(설정!$B$47="실측",ISNUMBER('Expert 실측'!$D$10)),MIN(모델!$D$36,'Expert 실측'!$D$10),'Expert 실측'!$D$20)/모델!$D$36,"-") -> 1 | E30: =IF(모델!$E$36>1,IF(AND(설정!$B$47="실측",ISNUMBER('Expert 실측'!$E$10)),MIN(모델!$E$36,'Expert 실측'!$E$10),'Expert 실측'!$E$20)/모델!$E$36,"-") -> 1 | F30: =IF(모델!$F$36>1,IF(AND(설정!$B$47="실측",ISNUMBER('Expert 실측'!$F$10)),MIN(모델!$F$36,'Expert 실측'!$F$10),'Expert 실측'!$F$20)/모델!$F$36,"-") -> -
A31: =설정!$F$54 -> 2048 | B31: =IF(모델!$B$36>1,IF(AND(설정!$B$47="실측",ISNUMBER('Expert 실측'!$B$11)),MIN(모델!$B$36,'Expert 실측'!$B$11),'Expert 실측'!$B$21)/모델!$B$36,"-") -> - | C31: =IF(모델!$C$36>1,IF(AND(설정!$B$47="실측",ISNUMBER('Expert 실측'!$C$11)),MIN(모델!$C$36,'Expert 실측'!$C$11),'Expert 실측'!$C$21)/모델!$C$36,"-") -> 1 | D31: =IF(모델!$D$36>1,IF(AND(설정!$B$47="실측",ISNUMBER('Expert 실측'!$D$11)),MIN(모델!$D$36,'Expert 실측'!$D$11),'Expert 실측'!$D$21)/모델!$D$36,"-") -> 1 | E31: =IF(모델!$E$36>1,IF(AND(설정!$B$47="실측",ISNUMBER('Expert 실측'!$E$11)),MIN(모델!$E$36,'Expert 실측'!$E$11),'Expert 실측'!$E$21)/모델!$E$36,"-") -> 1 | F31: =IF(모델!$F$36>1,IF(AND(설정!$B$47="실측",ISNUMBER('Expert 실측'!$F$11)),MIN(모델!$F$36,'Expert 실측'!$F$11),'Expert 실측'!$F$21)/모델!$F$36,"-") -> -
A32: =설정!$G$54 -> 4096 | B32: =IF(모델!$B$36>1,IF(AND(설정!$B$47="실측",ISNUMBER('Expert 실측'!$B$12)),MIN(모델!$B$36,'Expert 실측'!$B$12),'Expert 실측'!$B$22)/모델!$B$36,"-") -> - | C32: =IF(모델!$C$36>1,IF(AND(설정!$B$47="실측",ISNUMBER('Expert 실측'!$C$12)),MIN(모델!$C$36,'Expert 실측'!$C$12),'Expert 실측'!$C$22)/모델!$C$36,"-") -> 1 | D32: =IF(모델!$D$36>1,IF(AND(설정!$B$47="실측",ISNUMBER('Expert 실측'!$D$12)),MIN(모델!$D$36,'Expert 실측'!$D$12),'Expert 실측'!$D$22)/모델!$D$36,"-") -> 1 | E32: =IF(모델!$E$36>1,IF(AND(설정!$B$47="실측",ISNUMBER('Expert 실측'!$E$12)),MIN(모델!$E$36,'Expert 실측'!$E$12),'Expert 실측'!$E$22)/모델!$E$36,"-") -> 1 | F32: =IF(모델!$F$36>1,IF(AND(설정!$B$47="실측",ISNUMBER('Expert 실측'!$F$12)),MIN(모델!$F$36,'Expert 실측'!$F$12),'Expert 실측'!$F$22)/모델!$F$36,"-") -> -
A33: =설정!$H$54 -> 8192 | B33: =IF(모델!$B$36>1,IF(AND(설정!$B$47="실측",ISNUMBER('Expert 실측'!$B$13)),MIN(모델!$B$36,'Expert 실측'!$B$13),'Expert 실측'!$B$23)/모델!$B$36,"-") -> - | C33: =IF(모델!$C$36>1,IF(AND(설정!$B$47="실측",ISNUMBER('Expert 실측'!$C$13)),MIN(모델!$C$36,'Expert 실측'!$C$13),'Expert 실측'!$C$23)/모델!$C$36,"-") -> 1 | D33: =IF(모델!$D$36>1,IF(AND(설정!$B$47="실측",ISNUMBER('Expert 실측'!$D$13)),MIN(모델!$D$36,'Expert 실측'!$D$13),'Expert 실측'!$D$23)/모델!$D$36,"-") -> 1 | E33: =IF(모델!$E$36>1,IF(AND(설정!$B$47="실측",ISNUMBER('Expert 실측'!$E$13)),MIN(모델!$E$36,'Expert 실측'!$E$13),'Expert 실측'!$E$23)/모델!$E$36,"-") -> 1 | F33: =IF(모델!$F$36>1,IF(AND(설정!$B$47="실측",ISNUMBER('Expert 실측'!$F$13)),MIN(모델!$F$36,'Expert 실측'!$F$13),'Expert 실측'!$F$23)/모델!$F$36,"-") -> -
A34: Dense 모델(Expert 수 0)은 입력해도 무시됩니다. 실측값은 layer별 사용 수의 평균이며, 가중치 읽기량은 layer별 사용 수의 합에 비례하므로 평균으로 넣어도 총량은 정확합니다.

Sheet 계산_모델1
A1: =모델!B6&" — 계산 상세" -> Llama 3.1 8B Instruct — 계산 상세
A2: 모든 셀 자동 계산. 행렬마다 roofline(연산 시간과 DRAM 시간 중 큰 값)을 적용해 합산합니다. 개수가 0인 행렬은 해당 블록이 없는 모델입니다.
A4: 행렬 | B4: K (입력) | C4: N (출력) | D4: 개수 | E4: 종류 | F4: 경량화 구분 | G4: Weight bit | H4: B/param | I4: 실효 ops/s
A5: full.q_proj | B5: =모델!$B$8 -> 4096 | C5: =모델!$B$13*모델!$B$15*모델!$B$16 -> 4096 | D5: =모델!$B$12 -> 32 | E5: dense | F5: Attention | G5: =설정!$B$27 -> 4 | H5: =(설정!$B$27/8+IF(설정!$C$27=0,설정!$D$27/8/MAX(1,$B$5),설정!$D$27/8/설정!$C$27)) -> 0.515625 | I5: =설정!$B$63 -> 24000000000000
A6: full.k_proj | B6: =모델!$B$8 -> 4096 | C6: =모델!$B$14*모델!$B$15 -> 1024 | D6: =모델!$B$12 -> 32 | E6: dense | F6: Attention | G6: =설정!$B$27 -> 4 | H6: =(설정!$B$27/8+IF(설정!$C$27=0,설정!$D$27/8/MAX(1,$B$6),설정!$D$27/8/설정!$C$27)) -> 0.515625 | I6: =설정!$B$63 -> 24000000000000
A7: full.v_proj | B7: =모델!$B$8 -> 4096 | C7: =모델!$B$14*모델!$B$15 -> 1024 | D7: =모델!$B$12*모델!$B$17 -> 32 | E7: dense | F7: Attention | G7: =설정!$B$27 -> 4 | H7: =(설정!$B$27/8+IF(설정!$C$27=0,설정!$D$27/8/MAX(1,$B$7),설정!$D$27/8/설정!$C$27)) -> 0.515625 | I7: =설정!$B$63 -> 24000000000000
A8: full.o_proj | B8: =모델!$B$13*모델!$B$15 -> 4096 | C8: =모델!$B$8 -> 4096 | D8: =모델!$B$12 -> 32 | E8: dense | F8: Attention | G8: =설정!$B$27 -> 4 | H8: =(설정!$B$27/8+IF(설정!$C$27=0,설정!$D$27/8/MAX(1,$B$8),설정!$D$27/8/설정!$C$27)) -> 0.515625 | I8: =설정!$B$63 -> 24000000000000
A9: swa.q_proj | B9: =모델!$B$8 -> 4096 | C9: =모델!$B$21*모델!$B$23 -> 0 | D9: =모델!$B$19 -> 0 | E9: dense | F9: Attention | G9: =설정!$B$27 -> 4 | H9: =(설정!$B$27/8+IF(설정!$C$27=0,설정!$D$27/8/MAX(1,$B$9),설정!$D$27/8/설정!$C$27)) -> 0.515625 | I9: =설정!$B$63 -> 24000000000000
A10: swa.k_proj | B10: =모델!$B$8 -> 4096 | C10: =모델!$B$22*모델!$B$23 -> 0 | D10: =모델!$B$19 -> 0 | E10: dense | F10: Attention | G10: =설정!$B$27 -> 4 | H10: =(설정!$B$27/8+IF(설정!$C$27=0,설정!$D$27/8/MAX(1,$B$10),설정!$D$27/8/설정!$C$27)) -> 0.515625 | I10: =설정!$B$63 -> 24000000000000
A11: swa.v_proj | B11: =모델!$B$8 -> 4096 | C11: =모델!$B$22*모델!$B$23 -> 0 | D11: =모델!$B$19*모델!$B$24 -> 0 | E11: dense | F11: Attention | G11: =설정!$B$27 -> 4 | H11: =(설정!$B$27/8+IF(설정!$C$27=0,설정!$D$27/8/MAX(1,$B$11),설정!$D$27/8/설정!$C$27)) -> 0.515625 | I11: =설정!$B$63 -> 24000000000000
A12: swa.o_proj | B12: =모델!$B$21*모델!$B$23 -> 0 | C12: =모델!$B$8 -> 4096 | D12: =모델!$B$19 -> 0 | E12: dense | F12: Attention | G12: =설정!$B$27 -> 4 | H12: =(설정!$B$27/8+IF(설정!$C$27=0,설정!$D$27/8/MAX(1,$B$12),설정!$D$27/8/설정!$C$27)) -> 0.515625 | I12: =설정!$B$63 -> 24000000000000
A13: gdn.in_proj_qkv | B13: =모델!$B$8 -> 4096 | C13: =모델!$B$52 -> 0 | D13: =모델!$B$26 -> 0 | E13: dense | F13: Linear attn (GDN) | G13: =설정!$B$28 -> 4 | H13: =(설정!$B$28/8+IF(설정!$C$28=0,설정!$D$28/8/MAX(1,$B$13),설정!$D$28/8/설정!$C$28)) -> 0.515625 | I13: =설정!$B$64 -> 24000000000000
A14: gdn.in_proj_z | B14: =모델!$B$8 -> 4096 | C14: =모델!$B$29*모델!$B$30 -> 0 | D14: =모델!$B$26 -> 0 | E14: dense | F14: Linear attn (GDN) | G14: =설정!$B$28 -> 4 | H14: =(설정!$B$28/8+IF(설정!$C$28=0,설정!$D$28/8/MAX(1,$B$14),설정!$D$28/8/설정!$C$28)) -> 0.515625 | I14: =설정!$B$64 -> 24000000000000
A15: gdn.in_proj_ab | B15: =모델!$B$8 -> 4096 | C15: =2*모델!$B$29 -> 0 | D15: =모델!$B$26 -> 0 | E15: dense | F15: Linear attn (GDN) | G15: =설정!$B$28 -> 4 | H15: =(설정!$B$28/8+IF(설정!$C$28=0,설정!$D$28/8/MAX(1,$B$15),설정!$D$28/8/설정!$C$28)) -> 0.515625 | I15: =설정!$B$64 -> 24000000000000
A16: gdn.out_proj | B16: =모델!$B$29*모델!$B$30 -> 0 | C16: =모델!$B$8 -> 4096 | D16: =모델!$B$26 -> 0 | E16: dense | F16: Linear attn (GDN) | G16: =설정!$B$28 -> 4 | H16: =(설정!$B$28/8+IF(설정!$C$28=0,설정!$D$28/8/MAX(1,$B$16),설정!$D$28/8/설정!$C$28)) -> 0.515625 | I16: =설정!$B$64 -> 24000000000000
A17: router | B17: =모델!$B$8 -> 4096 | C17: =모델!$B$36 -> 0 | D17: =IF(모델!$B$36>1,모델!$B$7,0) -> 0 | E17: dense | F17: Router (MoE) | G17: =설정!$B$30 -> 8 | H17: =(설정!$B$30/8+IF(설정!$C$30=0,설정!$D$30/8/MAX(1,$B$17),설정!$D$30/8/설정!$C$30)) -> 1.015625 | I17: =설정!$B$66 -> 24000000000000
A18: ffn.gate_proj | B18: =모델!$B$8 -> 4096 | C18: =모델!$B$34 -> 14336 | D18: =IF(AND(모델!$B$34>0,모델!$B$35>=3),모델!$B$7,0) -> 32 | E18: dense | F18: FFN / Expert | G18: =설정!$B$29 -> 4 | H18: =(설정!$B$29/8+IF(설정!$C$29=0,설정!$D$29/8/MAX(1,$B$18),설정!$D$29/8/설정!$C$29)) -> 0.515625 | I18: =설정!$B$65 -> 24000000000000
A19: ffn.up_proj | B19: =모델!$B$8 -> 4096 | C19: =모델!$B$34 -> 14336 | D19: =IF(모델!$B$34>0,모델!$B$7,0) -> 32 | E19: dense | F19: FFN / Expert | G19: =설정!$B$29 -> 4 | H19: =(설정!$B$29/8+IF(설정!$C$29=0,설정!$D$29/8/MAX(1,$B$19),설정!$D$29/8/설정!$C$29)) -> 0.515625 | I19: =설정!$B$65 -> 24000000000000
A20: ffn.down_proj | B20: =모델!$B$34 -> 14336 | C20: =모델!$B$8 -> 4096 | D20: =IF(모델!$B$34>0,모델!$B$7,0) -> 32 | E20: dense | F20: FFN / Expert | G20: =설정!$B$29 -> 4 | H20: =(설정!$B$29/8+IF(설정!$C$29=0,설정!$D$29/8/MAX(1,$B$20),설정!$D$29/8/설정!$C$29)) -> 0.515625 | I20: =설정!$B$65 -> 24000000000000
A21: expert.gate_proj | B21: =모델!$B$8 -> 4096 | C21: =모델!$B$38 -> 0 | D21: =IF(AND(모델!$B$36>1,모델!$B$35>=3),모델!$B$7,0) -> 0 | E21: expert | F21: FFN / Expert | G21: =설정!$B$29 -> 4 | H21: =(설정!$B$29/8+IF(설정!$C$29=0,설정!$D$29/8/MAX(1,$B$21),설정!$D$29/8/설정!$C$29)) -> 0.515625 | I21: =설정!$B$65 -> 24000000000000
A22: expert.up_proj | B22: =모델!$B$8 -> 4096 | C22: =모델!$B$38 -> 0 | D22: =IF(모델!$B$36>1,모델!$B$7,0) -> 0 | E22: expert | F22: FFN / Expert | G22: =설정!$B$29 -> 4 | H22: =(설정!$B$29/8+IF(설정!$C$29=0,설정!$D$29/8/MAX(1,$B$22),설정!$D$29/8/설정!$C$29)) -> 0.515625 | I22: =설정!$B$65 -> 24000000000000
A23: expert.down_proj | B23: =모델!$B$38 -> 0 | C23: =모델!$B$8 -> 4096 | D23: =IF(모델!$B$36>1,모델!$B$7,0) -> 0 | E23: expert | F23: FFN / Expert | G23: =설정!$B$29 -> 4 | H23: =(설정!$B$29/8+IF(설정!$C$29=0,설정!$D$29/8/MAX(1,$B$23),설정!$D$29/8/설정!$C$29)) -> 0.515625 | I23: =설정!$B$65 -> 24000000000000
A24: lm_head | B24: =모델!$B$8 -> 4096 | C24: =모델!$B$9 -> 128256 | D24: =1 -> 1 | E24: head | F24: LM head | G24: =설정!$B$31 -> 4 | H24: =(설정!$B$31/8+IF(설정!$C$31=0,설정!$D$31/8/MAX(1,$B$24),설정!$D$31/8/설정!$C$31)) -> 0.515625 | I24: =설정!$B$67 -> 24000000000000
A25: expert 종류는 MoE에서 expert 수만큼 존재하며, 선택된 expert만 읽고 계산합니다.
A27: ① 프리필 (TTFT)
A28: 입력 길이 N | B28: =설정!$B$54 -> 128 | C28: =설정!$C$54 -> 256 | D28: =설정!$D$54 -> 512 | E28: =설정!$E$54 -> 1024 | F28: =설정!$F$54 -> 2048 | G28: =설정!$G$54 -> 4096 | H28: =설정!$H$54 -> 8192
A29: 사용되는 expert 수 (layer당 기대값) | B29: =IF(모델!$B$36>1,IF(AND(설정!$B$47="실측",ISNUMBER('Expert 실측'!$B$7)),MIN(모델!$B$36,MAX(1,'Expert 실측'!$B$7)),모델!$B$36*(1-EXP(MAX(-700,B28*LN(1-MIN(모델!$B$37/모델!$B$36,0.999999)))))),1) -> 1 | C29: =IF(모델!$B$36>1,IF(AND(설정!$B$47="실측",ISNUMBER('Expert 실측'!$B$8)),MIN(모델!$B$36,MAX(1,'Expert 실측'!$B$8)),모델!$B$36*(1-EXP(MAX(-700,C28*LN(1-MIN(모델!$B$37/모델!$B$36,0.999999)))))),1) -> 1 | D29: =IF(모델!$B$36>1,IF(AND(설정!$B$47="실측",ISNUMBER('Expert 실측'!$B$9)),MIN(모델!$B$36,MAX(1,'Expert 실측'!$B$9)),모델!$B$36*(1-EXP(MAX(-700,D28*LN(1-MIN(모델!$B$37/모델!$B$36,0.999999)))))),1) -> 1 | E29: =IF(모델!$B$36>1,IF(AND(설정!$B$47="실측",ISNUMBER('Expert 실측'!$B$10)),MIN(모델!$B$36,MAX(1,'Expert 실측'!$B$10)),모델!$B$36*(1-EXP(MAX(-700,E28*LN(1-MIN(모델!$B$37/모델!$B$36,0.999999)))))),1) -> 1 | F29: =IF(모델!$B$36>1,IF(AND(설정!$B$47="실측",ISNUMBER('Expert 실측'!$B$11)),MIN(모델!$B$36,MAX(1,'Expert 실측'!$B$11)),모델!$B$36*(1-EXP(MAX(-700,F28*LN(1-MIN(모델!$B$37/모델!$B$36,0.999999)))))),1) -> 1 | G29: =IF(모델!$B$36>1,IF(AND(설정!$B$47="실측",ISNUMBER('Expert 실측'!$B$12)),MIN(모델!$B$36,MAX(1,'Expert 실측'!$B$12)),모델!$B$36*(1-EXP(MAX(-700,G28*LN(1-MIN(모델!$B$37/모델!$B$36,0.999999)))))),1) -> 1 | H29: =IF(모델!$B$36>1,IF(AND(설정!$B$47="실측",ISNUMBER('Expert 실측'!$B$13)),MIN(모델!$B$36,MAX(1,'Expert 실측'!$B$13)),모델!$B$36*(1-EXP(MAX(-700,H28*LN(1-MIN(모델!$B$37/모델!$B$36,0.999999)))))),1) -> 1
A30: expert 사용 비율 (균등 시 1−(1−k/E)^N) | B30: =IF(모델!$B$36>1,B29/모델!$B$36,1) -> 1 | C30: =IF(모델!$B$36>1,C29/모델!$B$36,1) -> 1 | D30: =IF(모델!$B$36>1,D29/모델!$B$36,1) -> 1 | E30: =IF(모델!$B$36>1,E29/모델!$B$36,1) -> 1 | F30: =IF(모델!$B$36>1,F29/모델!$B$36,1) -> 1 | G30: =IF(모델!$B$36>1,G29/모델!$B$36,1) -> 1 | H30: =IF(모델!$B$36>1,H29/모델!$B$36,1) -> 1 | I30: 균등: 토큰 하나가 특정 expert를 안 고를 확률 (1−k/E)의 N제곱. 실측 모드면 Expert 실측 시트 값
A31: expert당 토큰 수 (평균) | B31: =IF(모델!$B$36>1,B28*모델!$B$37/B29,B28) -> 128 | C31: =IF(모델!$B$36>1,C28*모델!$B$37/C29,C28) -> 256 | D31: =IF(모델!$B$36>1,D28*모델!$B$37/D29,D28) -> 512 | E31: =IF(모델!$B$36>1,E28*모델!$B$37/E29,E28) -> 1024 | F31: =IF(모델!$B$36>1,F28*모델!$B$37/F29,F28) -> 2048 | G31: =IF(모델!$B$36>1,G28*모델!$B$37/G29,G28) -> 4096 | H31: =IF(모델!$B$36>1,H28*모델!$B$37/H29,H28) -> 8192
A32: full.q_proj 연산량 (ops) | B32: =($D$5)*2*(B$28)*$B$5*$C$5 -> 137438953472 | C32: =($D$5)*2*(C$28)*$B$5*$C$5 -> 274877906944 | D32: =($D$5)*2*(D$28)*$B$5*$C$5 -> 549755813888 | E32: =($D$5)*2*(E$28)*$B$5*$C$5 -> 1099511627776 | F32: =($D$5)*2*(F$28)*$B$5*$C$5 -> 2199023255552 | G32: =($D$5)*2*(G$28)*$B$5*$C$5 -> 4398046511104 | H32: =($D$5)*2*(H$28)*$B$5*$C$5 -> 8796093022208
A33: full.q_proj DRAM 트래픽 (B) | B33: =($D$5)*MIN(($B$5*$C$5*$H$5)*MAX(1,ROUNDUP(((B$28)*$B$5*설정!$B$57)/설정!$B$61,0))+((B$28)*$B$5*설정!$B$57)+((B$28)*$C$5*설정!$B$57),($B$5*$C$5*$H$5)+((B$28)*$B$5*설정!$B$57)*MAX(1,ROUNDUP(($B$5*$C$5*$H$5)/설정!$B$61,0))+((B$28)*$C$5*설정!$B$57)) -> 310378496 | C33: =($D$5)*MIN(($B$5*$C$5*$H$5)*MAX(1,ROUNDUP(((C$28)*$B$5*설정!$B$57)/설정!$B$61,0))+((C$28)*$B$5*설정!$B$57)+((C$28)*$C$5*설정!$B$57),($B$5*$C$5*$H$5)+((C$28)*$B$5*설정!$B$57)*MAX(1,ROUNDUP(($B$5*$C$5*$H$5)/설정!$B$61,0))+((C$28)*$C$5*설정!$B$57)) -> 343932928 | D33: =($D$5)*MIN(($B$5*$C$5*$H$5)*MAX(1,ROUNDUP(((D$28)*$B$5*설정!$B$57)/설정!$B$61,0))+((D$28)*$B$5*설정!$B$57)+((D$28)*$C$5*설정!$B$57),($B$5*$C$5*$H$5)+((D$28)*$B$5*설정!$B$57)*MAX(1,ROUNDUP(($B$5*$C$5*$H$5)/설정!$B$61,0))+((D$28)*$C$5*설정!$B$57)) -> 687865856 | E33: =($D$5)*MIN(($B$5*$C$5*$H$5)*MAX(1,ROUNDUP(((E$28)*$B$5*설정!$B$57)/설정!$B$61,0))+((E$28)*$B$5*설정!$B$57)+((E$28)*$C$5*설정!$B$57),($B$5*$C$5*$H$5)+((E$28)*$B$5*설정!$B$57)*MAX(1,ROUNDUP(($B$5*$C$5*$H$5)/설정!$B$61,0))+((E$28)*$C$5*설정!$B$57)) -> 1098907648 | F33: =($D$5)*MIN(($B$5*$C$5*$H$5)*MAX(1,ROUNDUP(((F$28)*$B$5*설정!$B$57)/설정!$B$61,0))+((F$28)*$B$5*설정!$B$57)+((F$28)*$C$5*설정!$B$57),($B$5*$C$5*$H$5)+((F$28)*$B$5*설정!$B$57)*MAX(1,ROUNDUP(($B$5*$C$5*$H$5)/설정!$B$61,0))+((F$28)*$C$5*설정!$B$57)) -> 1920991232 | G33: =($D$5)*MIN(($B$5*$C$5*$H$5)*MAX(1,ROUNDUP(((G$28)*$B$5*설정!$B$57)/설정!$B$61,0))+((G$28)*$B$5*설정!$B$57)+((G$28)*$C$5*설정!$B$57),($B$5*$C$5*$H$5)+((G$28)*$B$5*설정!$B$57)*MAX(1,ROUNDUP(($B$5*$C$5*$H$5)/설정!$B$61,0))+((G$28)*$C$5*설정!$B$57)) -> 3841982464 | H33: =($D$5)*MIN(($B$5*$C$5*$H$5)*MAX(1,ROUNDUP(((H$28)*$B$5*설정!$B$57)/설정!$B$61,0))+((H$28)*$B$5*설정!$B$57)+((H$28)*$C$5*설정!$B$57),($B$5*$C$5*$H$5)+((H$28)*$B$5*설정!$B$57)*MAX(1,ROUNDUP(($B$5*$C$5*$H$5)/설정!$B$61,0))+((H$28)*$C$5*설정!$B$57)) -> 7683964928
A34: full.q_proj 시간 (ms) | B34: =MAX(B32/$I$5,B33/설정!$B$60)*1000 -> 6.0858529 | C34: =MAX(C32/$I$5,C33/설정!$B$60)*1000 -> 11.453246 | D34: =MAX(D32/$I$5,D33/설정!$B$60)*1000 -> 22.906492 | E34: =MAX(E32/$I$5,E33/설정!$B$60)*1000 -> 45.812984 | F34: =MAX(F32/$I$5,F33/설정!$B$60)*1000 -> 91.625969 | G34: =MAX(G32/$I$5,G33/설정!$B$60)*1000 -> 183.25194 | H34: =MAX(H32/$I$5,H33/설정!$B$60)*1000 -> 366.50388
A35: full.k_proj 연산량 (ops) | B35: =($D$6)*2*(B$28)*$B$6*$C$6 -> 34359738368 | C35: =($D$6)*2*(C$28)*$B$6*$C$6 -> 68719476736 | D35: =($D$6)*2*(D$28)*$B$6*$C$6 -> 137438953472 | E35: =($D$6)*2*(E$28)*$B$6*$C$6 -> 274877906944 | F35: =($D$6)*2*(F$28)*$B$6*$C$6 -> 549755813888 | G35: =($D$6)*2*(G$28)*$B$6*$C$6 -> 1099511627776 | H35: =($D$6)*2*(H$28)*$B$6*$C$6 -> 2199023255552
A36: full.k_proj DRAM 트래픽 (B) | B36: =($D$6)*MIN(($B$6*$C$6*$H$6)*MAX(1,ROUNDUP(((B$28)*$B$6*설정!$B$57)/설정!$B$61,0))+((B$28)*$B$6*설정!$B$57)+((B$28)*$C$6*설정!$B$57),($B$6*$C$6*$H$6)+((B$28)*$B$6*설정!$B$57)*MAX(1,ROUNDUP(($B$6*$C$6*$H$6)/설정!$B$61,0))+((B$28)*$C$6*설정!$B$57)) -> 90177536 | C36: =($D$6)*MIN(($B$6*$C$6*$H$6)*MAX(1,ROUNDUP(((C$28)*$B$6*설정!$B$57)/설정!$B$61,0))+((C$28)*$B$6*설정!$B$57)+((C$28)*$C$6*설정!$B$57),($B$6*$C$6*$H$6)+((C$28)*$B$6*설정!$B$57)*MAX(1,ROUNDUP(($B$6*$C$6*$H$6)/설정!$B$61,0))+((C$28)*$C$6*설정!$B$57)) -> 111149056 | D36: =($D$6)*MIN(($B$6*$C$6*$H$6)*MAX(1,ROUNDUP(((D$28)*$B$6*설정!$B$57)/설정!$B$61,0))+((D$28)*$B$6*설정!$B$57)+((D$28)*$C$6*설정!$B$57),($B$6*$C$6*$H$6)+((D$28)*$B$6*설정!$B$57)*MAX(1,ROUNDUP(($B$6*$C$6*$H$6)/설정!$B$61,0))+((D$28)*$C$6*설정!$B$57)) -> 220200960 | E36: =($D$6)*MIN(($B$6*$C$6*$H$6)*MAX(1,ROUNDUP(((E$28)*$B$6*설정!$B$57)/설정!$B$61,0))+((E$28)*$B$6*설정!$B$57)+((E$28)*$C$6*설정!$B$57),($B$6*$C$6*$H$6)+((E$28)*$B$6*설정!$B$57)*MAX(1,ROUNDUP(($B$6*$C$6*$H$6)/설정!$B$61,0))+((E$28)*$C$6*설정!$B$57)) -> 371195904 | F36: =($D$6)*MIN(($B$6*$C$6*$H$6)*MAX(1,ROUNDUP(((F$28)*$B$6*설정!$B$57)/설정!$B$61,0))+((F$28)*$B$6*설정!$B$57)+((F$28)*$C$6*설정!$B$57),($B$6*$C$6*$H$6)+((F$28)*$B$6*설정!$B$57)*MAX(1,ROUNDUP(($B$6*$C$6*$H$6)/설정!$B$61,0))+((F$28)*$C$6*설정!$B$57)) -> 673185792 | G36: =($D$6)*MIN(($B$6*$C$6*$H$6)*MAX(1,ROUNDUP(((G$28)*$B$6*설정!$B$57)/설정!$B$61,0))+((G$28)*$B$6*설정!$B$57)+((G$28)*$C$6*설정!$B$57),($B$6*$C$6*$H$6)+((G$28)*$B$6*설정!$B$57)*MAX(1,ROUNDUP(($B$6*$C$6*$H$6)/설정!$B$61,0))+((G$28)*$C$6*설정!$B$57)) -> 1277165568 | H36: =($D$6)*MIN(($B$6*$C$6*$H$6)*MAX(1,ROUNDUP(((H$28)*$B$6*설정!$B$57)/설정!$B$61,0))+((H$28)*$B$6*설정!$B$57)+((H$28)*$C$6*설정!$B$57),($B$6*$C$6*$H$6)+((H$28)*$B$6*설정!$B$57)*MAX(1,ROUNDUP(($B$6*$C$6*$H$6)/설정!$B$61,0))+((H$28)*$C$6*설정!$B$57)) -> 2485125120
A37: full.k_proj 시간 (ms) | B37: =MAX(B35/$I$6,B36/설정!$B$60)*1000 -> 1.768187 | C37: =MAX(C35/$I$6,C36/설정!$B$60)*1000 -> 2.8633115 | D37: =MAX(D35/$I$6,D36/설정!$B$60)*1000 -> 5.7266231 | E37: =MAX(E35/$I$6,E36/설정!$B$60)*1000 -> 11.453246 | F37: =MAX(F35/$I$6,F36/설정!$B$60)*1000 -> 22.906492 | G37: =MAX(G35/$I$6,G36/설정!$B$60)*1000 -> 45.812984 | H37: =MAX(H35/$I$6,H36/설정!$B$60)*1000 -> 91.625969
A38: full.v_proj 연산량 (ops) | B38: =($D$7)*2*(B$28)*$B$7*$C$7 -> 34359738368 | C38: =($D$7)*2*(C$28)*$B$7*$C$7 -> 68719476736 | D38: =($D$7)*2*(D$28)*$B$7*$C$7 -> 137438953472 | E38: =($D$7)*2*(E$28)*$B$7*$C$7 -> 274877906944 | F38: =($D$7)*2*(F$28)*$B$7*$C$7 -> 549755813888 | G38: =($D$7)*2*(G$28)*$B$7*$C$7 -> 1099511627776 | H38: =($D$7)*2*(H$28)*$B$7*$C$7 -> 2199023255552
A39: full.v_proj DRAM 트래픽 (B) | B39: =($D$7)*MIN(($B$7*$C$7*$H$7)*MAX(1,ROUNDUP(((B$28)*$B$7*설정!$B$57)/설정!$B$61,0))+((B$28)*$B$7*설정!$B$57)+((B$28)*$C$7*설정!$B$57),($B$7*$C$7*$H$7)+((B$28)*$B$7*설정!$B$57)*MAX(1,ROUNDUP(($B$7*$C$7*$H$7)/설정!$B$61,0))+((B$28)*$C$7*설정!$B$57)) -> 90177536 | C39: =($D$7)*MIN(($B$7*$C$7*$H$7)*MAX(1,ROUNDUP(((C$28)*$B$7*설정!$B$57)/설정!$B$61,0))+((C$28)*$B$7*설정!$B$57)+((C$28)*$C$7*설정!$B$57),($B$7*$C$7*$H$7)+((C$28)*$B$7*설정!$B$57)*MAX(1,ROUNDUP(($B$7*$C$7*$H$7)/설정!$B$61,0))+((C$28)*$C$7*설정!$B$57)) -> 111149056 | D39: =($D$7)*MIN(($B$7*$C$7*$H$7)*MAX(1,ROUNDUP(((D$28)*$B$7*설정!$B$57)/설정!$B$61,0))+((D$28)*$B$7*설정!$B$57)+((D$28)*$C$7*설정!$B$57),($B$7*$C$7*$H$7)+((D$28)*$B$7*설정!$B$57)*MAX(1,ROUNDUP(($B$7*$C$7*$H$7)/설정!$B$61,0))+((D$28)*$C$7*설정!$B$57)) -> 220200960 | E39: =($D$7)*MIN(($B$7*$C$7*$H$7)*MAX(1,ROUNDUP(((E$28)*$B$7*설정!$B$57)/설정!$B$61,0))+((E$28)*$B$7*설정!$B$57)+((E$28)*$C$7*설정!$B$57),($B$7*$C$7*$H$7)+((E$28)*$B$7*설정!$B$57)*MAX(1,ROUNDUP(($B$7*$C$7*$H$7)/설정!$B$61,0))+((E$28)*$C$7*설정!$B$57)) -> 371195904 | F39: =($D$7)*MIN(($B$7*$C$7*$H$7)*MAX(1,ROUNDUP(((F$28)*$B$7*설정!$B$57)/설정!$B$61,0))+((F$28)*$B$7*설정!$B$57)+((F$28)*$C$7*설정!$B$57),($B$7*$C$7*$H$7)+((F$28)*$B$7*설정!$B$57)*MAX(1,ROUNDUP(($B$7*$C$7*$H$7)/설정!$B$61,0))+((F$28)*$C$7*설정!$B$57)) -> 673185792 | G39: =($D$7)*MIN(($B$7*$C$7*$H$7)*MAX(1,ROUNDUP(((G$28)*$B$7*설정!$B$57)/설정!$B$61,0))+((G$28)*$B$7*설정!$B$57)+((G$28)*$C$7*설정!$B$57),($B$7*$C$7*$H$7)+((G$28)*$B$7*설정!$B$57)*MAX(1,ROUNDUP(($B$7*$C$7*$H$7)/설정!$B$61,0))+((G$28)*$C$7*설정!$B$57)) -> 1277165568 | H39: =($D$7)*MIN(($B$7*$C$7*$H$7)*MAX(1,ROUNDUP(((H$28)*$B$7*설정!$B$57)/설정!$B$61,0))+((H$28)*$B$7*설정!$B$57)+((H$28)*$C$7*설정!$B$57),($B$7*$C$7*$H$7)+((H$28)*$B$7*설정!$B$57)*MAX(1,ROUNDUP(($B$7*$C$7*$H$7)/설정!$B$61,0))+((H$28)*$C$7*설정!$B$57)) -> 2485125120
A40: full.v_proj 시간 (ms) | B40: =MAX(B38/$I$7,B39/설정!$B$60)*1000 -> 1.768187 | C40: =MAX(C38/$I$7,C39/설정!$B$60)*1000 -> 2.8633115 | D40: =MAX(D38/$I$7,D39/설정!$B$60)*1000 -> 5.7266231 | E40: =MAX(E38/$I$7,E39/설정!$B$60)*1000 -> 11.453246 | F40: =MAX(F38/$I$7,F39/설정!$B$60)*1000 -> 22.906492 | G40: =MAX(G38/$I$7,G39/설정!$B$60)*1000 -> 45.812984 | H40: =MAX(H38/$I$7,H39/설정!$B$60)*1000 -> 91.625969
A41: full.o_proj 연산량 (ops) | B41: =($D$8)*2*(B$28)*$B$8*$C$8 -> 137438953472 | C41: =($D$8)*2*(C$28)*$B$8*$C$8 -> 274877906944 | D41: =($D$8)*2*(D$28)*$B$8*$C$8 -> 549755813888 | E41: =($D$8)*2*(E$28)*$B$8*$C$8 -> 1099511627776 | F41: =($D$8)*2*(F$28)*$B$8*$C$8 -> 2199023255552 | G41: =($D$8)*2*(G$28)*$B$8*$C$8 -> 4398046511104 | H41: =($D$8)*2*(H$28)*$B$8*$C$8 -> 8796093022208
A42: full.o_proj DRAM 트래픽 (B) | B42: =($D$8)*MIN(($B$8*$C$8*$H$8)*MAX(1,ROUNDUP(((B$28)*$B$8*설정!$B$57)/설정!$B$61,0))+((B$28)*$B$8*설정!$B$57)+((B$28)*$C$8*설정!$B$57),($B$8*$C$8*$H$8)+((B$28)*$B$8*설정!$B$57)*MAX(1,ROUNDUP(($B$8*$C$8*$H$8)/설정!$B$61,0))+((B$28)*$C$8*설정!$B$57)) -> 310378496 | C42: =($D$8)*MIN(($B$8*$C$8*$H$8)*MAX(1,ROUNDUP(((C$28)*$B$8*설정!$B$57)/설정!$B$61,0))+((C$28)*$B$8*설정!$B$57)+((C$28)*$C$8*설정!$B$57),($B$8*$C$8*$H$8)+((C$28)*$B$8*설정!$B$57)*MAX(1,ROUNDUP(($B$8*$C$8*$H$8)/설정!$B$61,0))+((C$28)*$C$8*설정!$B$57)) -> 343932928 | D42: =($D$8)*MIN(($B$8*$C$8*$H$8)*MAX(1,ROUNDUP(((D$28)*$B$8*설정!$B$57)/설정!$B$61,0))+((D$28)*$B$8*설정!$B$57)+((D$28)*$C$8*설정!$B$57),($B$8*$C$8*$H$8)+((D$28)*$B$8*설정!$B$57)*MAX(1,ROUNDUP(($B$8*$C$8*$H$8)/설정!$B$61,0))+((D$28)*$C$8*설정!$B$57)) -> 687865856 | E42: =($D$8)*MIN(($B$8*$C$8*$H$8)*MAX(1,ROUNDUP(((E$28)*$B$8*설정!$B$57)/설정!$B$61,0))+((E$28)*$B$8*설정!$B$57)+((E$28)*$C$8*설정!$B$57),($B$8*$C$8*$H$8)+((E$28)*$B$8*설정!$B$57)*MAX(1,ROUNDUP(($B$8*$C$8*$H$8)/설정!$B$61,0))+((E$28)*$C$8*설정!$B$57)) -> 1098907648 | F42: =($D$8)*MIN(($B$8*$C$8*$H$8)*MAX(1,ROUNDUP(((F$28)*$B$8*설정!$B$57)/설정!$B$61,0))+((F$28)*$B$8*설정!$B$57)+((F$28)*$C$8*설정!$B$57),($B$8*$C$8*$H$8)+((F$28)*$B$8*설정!$B$57)*MAX(1,ROUNDUP(($B$8*$C$8*$H$8)/설정!$B$61,0))+((F$28)*$C$8*설정!$B$57)) -> 1920991232 | G42: =($D$8)*MIN(($B$8*$C$8*$H$8)*MAX(1,ROUNDUP(((G$28)*$B$8*설정!$B$57)/설정!$B$61,0))+((G$28)*$B$8*설정!$B$57)+((G$28)*$C$8*설정!$B$57),($B$8*$C$8*$H$8)+((G$28)*$B$8*설정!$B$57)*MAX(1,ROUNDUP(($B$8*$C$8*$H$8)/설정!$B$61,0))+((G$28)*$C$8*설정!$B$57)) -> 3841982464 | H42: =($D$8)*MIN(($B$8*$C$8*$H$8)*MAX(1,ROUNDUP(((H$28)*$B$8*설정!$B$57)/설정!$B$61,0))+((H$28)*$B$8*설정!$B$57)+((H$28)*$C$8*설정!$B$57),($B$8*$C$8*$H$8)+((H$28)*$B$8*설정!$B$57)*MAX(1,ROUNDUP(($B$8*$C$8*$H$8)/설정!$B$61,0))+((H$28)*$C$8*설정!$B$57)) -> 7683964928
...

Sheet 계산_모델2
A1: =모델!C6&" — 계산 상세" -> gpt-oss-20b — 계산 상세
A2: 모든 셀 자동 계산. 행렬마다 roofline(연산 시간과 DRAM 시간 중 큰 값)을 적용해 합산합니다. 개수가 0인 행렬은 해당 블록이 없는 모델입니다.
A4: 행렬 | B4: K (입력) | C4: N (출력) | D4: 개수 | E4: 종류 | F4: 경량화 구분 | G4: Weight bit | H4: B/param | I4: 실효 ops/s
A5: full.q_proj | B5: =모델!$C$8 -> 2880 | C5: =모델!$C$13*모델!$C$15*모델!$C$16 -> 4096 | D5: =모델!$C$12 -> 12 | E5: dense | F5: Attention | G5: =설정!$B$27 -> 4 | H5: =(설정!$B$27/8+IF(설정!$C$27=0,설정!$D$27/8/MAX(1,$B$5),설정!$D$27/8/설정!$C$27)) -> 0.515625 | I5: =설정!$B$63 -> 24000000000000
A6: full.k_proj | B6: =모델!$C$8 -> 2880 | C6: =모델!$C$14*모델!$C$15 -> 512 | D6: =모델!$C$12 -> 12 | E6: dense | F6: Attention | G6: =설정!$B$27 -> 4 | H6: =(설정!$B$27/8+IF(설정!$C$27=0,설정!$D$27/8/MAX(1,$B$6),설정!$D$27/8/설정!$C$27)) -> 0.515625 | I6: =설정!$B$63 -> 24000000000000
A7: full.v_proj | B7: =모델!$C$8 -> 2880 | C7: =모델!$C$14*모델!$C$15 -> 512 | D7: =모델!$C$12*모델!$C$17 -> 12 | E7: dense | F7: Attention | G7: =설정!$B$27 -> 4 | H7: =(설정!$B$27/8+IF(설정!$C$27=0,설정!$D$27/8/MAX(1,$B$7),설정!$D$27/8/설정!$C$27)) -> 0.515625 | I7: =설정!$B$63 -> 24000000000000
A8: full.o_proj | B8: =모델!$C$13*모델!$C$15 -> 4096 | C8: =모델!$C$8 -> 2880 | D8: =모델!$C$12 -> 12 | E8: dense | F8: Attention | G8: =설정!$B$27 -> 4 | H8: =(설정!$B$27/8+IF(설정!$C$27=0,설정!$D$27/8/MAX(1,$B$8),설정!$D$27/8/설정!$C$27)) -> 0.515625 | I8: =설정!$B$63 -> 24000000000000
A9: swa.q_proj | B9: =모델!$C$8 -> 2880 | C9: =모델!$C$21*모델!$C$23 -> 4096 | D9: =모델!$C$19 -> 12 | E9: dense | F9: Attention | G9: =설정!$B$27 -> 4 | H9: =(설정!$B$27/8+IF(설정!$C$27=0,설정!$D$27/8/MAX(1,$B$9),설정!$D$27/8/설정!$C$27)) -> 0.515625 | I9: =설정!$B$63 -> 24000000000000
A10: swa.k_proj | B10: =모델!$C$8 -> 2880 | C10: =모델!$C$22*모델!$C$23 -> 512 | D10: =모델!$C$19 -> 12 | E10: dense | F10: Attention | G10: =설정!$B$27 -> 4 | H10: =(설정!$B$27/8+IF(설정!$C$27=0,설정!$D$27/8/MAX(1,$B$10),설정!$D$27/8/설정!$C$27)) -> 0.515625 | I10: =설정!$B$63 -> 24000000000000
A11: swa.v_proj | B11: =모델!$C$8 -> 2880 | C11: =모델!$C$22*모델!$C$23 -> 512 | D11: =모델!$C$19*모델!$C$24 -> 12 | E11: dense | F11: Attention | G11: =설정!$B$27 -> 4 | H11: =(설정!$B$27/8+IF(설정!$C$27=0,설정!$D$27/8/MAX(1,$B$11),설정!$D$27/8/설정!$C$27)) -> 0.515625 | I11: =설정!$B$63 -> 24000000000000
A12: swa.o_proj | B12: =모델!$C$21*모델!$C$23 -> 4096 | C12: =모델!$C$8 -> 2880 | D12: =모델!$C$19 -> 12 | E12: dense | F12: Attention | G12: =설정!$B$27 -> 4 | H12: =(설정!$B$27/8+IF(설정!$C$27=0,설정!$D$27/8/MAX(1,$B$12),설정!$D$27/8/설정!$C$27)) -> 0.515625 | I12: =설정!$B$63 -> 24000000000000
A13: gdn.in_proj_qkv | B13: =모델!$C$8 -> 2880 | C13: =모델!$C$52 -> 0 | D13: =모델!$C$26 -> 0 | E13: dense | F13: Linear attn (GDN) | G13: =설정!$B$28 -> 4 | H13: =(설정!$B$28/8+IF(설정!$C$28=0,설정!$D$28/8/MAX(1,$B$13),설정!$D$28/8/설정!$C$28)) -> 0.515625 | I13: =설정!$B$64 -> 24000000000000
A14: gdn.in_proj_z | B14: =모델!$C$8 -> 2880 | C14: =모델!$C$29*모델!$C$30 -> 0 | D14: =모델!$C$26 -> 0 | E14: dense | F14: Linear attn (GDN) | G14: =설정!$B$28 -> 4 | H14: =(설정!$B$28/8+IF(설정!$C$28=0,설정!$D$28/8/MAX(1,$B$14),설정!$D$28/8/설정!$C$28)) -> 0.515625 | I14: =설정!$B$64 -> 24000000000000
A15: gdn.in_proj_ab | B15: =모델!$C$8 -> 2880 | C15: =2*모델!$C$29 -> 0 | D15: =모델!$C$26 -> 0 | E15: dense | F15: Linear attn (GDN) | G15: =설정!$B$28 -> 4 | H15: =(설정!$B$28/8+IF(설정!$C$28=0,설정!$D$28/8/MAX(1,$B$15),설정!$D$28/8/설정!$C$28)) -> 0.515625 | I15: =설정!$B$64 -> 24000000000000
A16: gdn.out_proj | B16: =모델!$C$29*모델!$C$30 -> 0 | C16: =모델!$C$8 -> 2880 | D16: =모델!$C$26 -> 0 | E16: dense | F16: Linear attn (GDN) | G16: =설정!$B$28 -> 4 | H16: =(설정!$B$28/8+IF(설정!$C$28=0,설정!$D$28/8/MAX(1,$B$16),설정!$D$28/8/설정!$C$28)) -> 0.515625 | I16: =설정!$B$64 -> 24000000000000
A17: router | B17: =모델!$C$8 -> 2880 | C17: =모델!$C$36 -> 32 | D17: =IF(모델!$C$36>1,모델!$C$7,0) -> 24 | E17: dense | F17: Router (MoE) | G17: =설정!$B$30 -> 8 | H17: =(설정!$B$30/8+IF(설정!$C$30=0,설정!$D$30/8/MAX(1,$B$17),설정!$D$30/8/설정!$C$30)) -> 1.015625 | I17: =설정!$B$66 -> 24000000000000
A18: ffn.gate_proj | B18: =모델!$C$8 -> 2880 | C18: =모델!$C$34 -> 0 | D18: =IF(AND(모델!$C$34>0,모델!$C$35>=3),모델!$C$7,0) -> 0 | E18: dense | F18: FFN / Expert | G18: =설정!$B$29 -> 4 | H18: =(설정!$B$29/8+IF(설정!$C$29=0,설정!$D$29/8/MAX(1,$B$18),설정!$D$29/8/설정!$C$29)) -> 0.515625 | I18: =설정!$B$65 -> 24000000000000
A19: ffn.up_proj | B19: =모델!$C$8 -> 2880 | C19: =모델!$C$34 -> 0 | D19: =IF(모델!$C$34>0,모델!$C$7,0) -> 0 | E19: dense | F19: FFN / Expert | G19: =설정!$B$29 -> 4 | H19: =(설정!$B$29/8+IF(설정!$C$29=0,설정!$D$29/8/MAX(1,$B$19),설정!$D$29/8/설정!$C$29)) -> 0.515625 | I19: =설정!$B$65 -> 24000000000000
A20: ffn.down_proj | B20: =모델!$C$34 -> 0 | C20: =모델!$C$8 -> 2880 | D20: =IF(모델!$C$34>0,모델!$C$7,0) -> 0 | E20: dense | F20: FFN / Expert | G20: =설정!$B$29 -> 4 | H20: =(설정!$B$29/8+IF(설정!$C$29=0,설정!$D$29/8/MAX(1,$B$20),설정!$D$29/8/설정!$C$29)) -> 0.515625 | I20: =설정!$B$65 -> 24000000000000
A21: expert.gate_proj | B21: =모델!$C$8 -> 2880 | C21: =모델!$C$38 -> 2880 | D21: =IF(AND(모델!$C$36>1,모델!$C$35>=3),모델!$C$7,0) -> 24 | E21: expert | F21: FFN / Expert | G21: =설정!$B$29 -> 4 | H21: =(설정!$B$29/8+IF(설정!$C$29=0,설정!$D$29/8/MAX(1,$B$21),설정!$D$29/8/설정!$C$29)) -> 0.515625 | I21: =설정!$B$65 -> 24000000000000
A22: expert.up_proj | B22: =모델!$C$8 -> 2880 | C22: =모델!$C$38 -> 2880 | D22: =IF(모델!$C$36>1,모델!$C$7,0) -> 24 | E22: expert | F22: FFN / Expert | G22: =설정!$B$29 -> 4 | H22: =(설정!$B$29/8+IF(설정!$C$29=0,설정!$D$29/8/MAX(1,$B$22),설정!$D$29/8/설정!$C$29)) -> 0.515625 | I22: =설정!$B$65 -> 24000000000000
A23: expert.down_proj | B23: =모델!$C$38 -> 2880 | C23: =모델!$C$8 -> 2880 | D23: =IF(모델!$C$36>1,모델!$C$7,0) -> 24 | E23: expert | F23: FFN / Expert | G23: =설정!$B$29 -> 4 | H23: =(설정!$B$29/8+IF(설정!$C$29=0,설정!$D$29/8/MAX(1,$B$23),설정!$D$29/8/설정!$C$29)) -> 0.515625 | I23: =설정!$B$65 -> 24000000000000
A24: lm_head | B24: =모델!$C$8 -> 2880 | C24: =모델!$C$9 -> 201088 | D24: =1 -> 1 | E24: head | F24: LM head | G24: =설정!$B$31 -> 4 | H24: =(설정!$B$31/8+IF(설정!$C$31=0,설정!$D$31/8/MAX(1,$B$24),설정!$D$31/8/설정!$C$31)) -> 0.515625 | I24: =설정!$B$67 -> 24000000000000
A25: expert 종류는 MoE에서 expert 수만큼 존재하며, 선택된 expert만 읽고 계산합니다.
A27: ① 프리필 (TTFT)
A28: 입력 길이 N | B28: =설정!$B$54 -> 128 | C28: =설정!$C$54 -> 256 | D28: =설정!$D$54 -> 512 | E28: =설정!$E$54 -> 1024 | F28: =설정!$F$54 -> 2048 | G28: =설정!$G$54 -> 4096 | H28: =설정!$H$54 -> 8192
A29: 사용되는 expert 수 (layer당 기대값) | B29: =IF(모델!$C$36>1,IF(AND(설정!$B$47="실측",ISNUMBER('Expert 실측'!$C$7)),MIN(모델!$C$36,MAX(1,'Expert 실측'!$C$7)),모델!$C$36*(1-EXP(MAX(-700,B28*LN(1-MIN(모델!$C$37/모델!$C$36,0.999999)))))),1) -> 31.999999 | C29: =IF(모델!$C$36>1,IF(AND(설정!$B$47="실측",ISNUMBER('Expert 실측'!$C$8)),MIN(모델!$C$36,MAX(1,'Expert 실측'!$C$8)),모델!$C$36*(1-EXP(MAX(-700,C28*LN(1-MIN(모델!$C$37/모델!$C$36,0.999999)))))),1) -> 32 | D29: =IF(모델!$C$36>1,IF(AND(설정!$B$47="실측",ISNUMBER('Expert 실측'!$C$9)),MIN(모델!$C$36,MAX(1,'Expert 실측'!$C$9)),모델!$C$36*(1-EXP(MAX(-700,D28*LN(1-MIN(모델!$C$37/모델!$C$36,0.999999)))))),1) -> 32 | E29: =IF(모델!$C$36>1,IF(AND(설정!$B$47="실측",ISNUMBER('Expert 실측'!$C$10)),MIN(모델!$C$36,MAX(1,'Expert 실측'!$C$10)),모델!$C$36*(1-EXP(MAX(-700,E28*LN(1-MIN(모델!$C$37/모델!$C$36,0.999999)))))),1) -> 32 | F29: =IF(모델!$C$36>1,IF(AND(설정!$B$47="실측",ISNUMBER('Expert 실측'!$C$11)),MIN(모델!$C$36,MAX(1,'Expert 실측'!$C$11)),모델!$C$36*(1-EXP(MAX(-700,F28*LN(1-MIN(모델!$C$37/모델!$C$36,0.999999)))))),1) -> 32 | G29: =IF(모델!$C$36>1,IF(AND(설정!$B$47="실측",ISNUMBER('Expert 실측'!$C$12)),MIN(모델!$C$36,MAX(1,'Expert 실측'!$C$12)),모델!$C$36*(1-EXP(MAX(-700,G28*LN(1-MIN(모델!$C$37/모델!$C$36,0.999999)))))),1) -> 32 | H29: =IF(모델!$C$36>1,IF(AND(설정!$B$47="실측",ISNUMBER('Expert 실측'!$C$13)),MIN(모델!$C$36,MAX(1,'Expert 실측'!$C$13)),모델!$C$36*(1-EXP(MAX(-700,H28*LN(1-MIN(모델!$C$37/모델!$C$36,0.999999)))))),1) -> 32
A30: expert 사용 비율 (균등 시 1−(1−k/E)^N) | B30: =IF(모델!$C$36>1,B29/모델!$C$36,1) -> 0.99999996 | C30: =IF(모델!$C$36>1,C29/모델!$C$36,1) -> 1 | D30: =IF(모델!$C$36>1,D29/모델!$C$36,1) -> 1 | E30: =IF(모델!$C$36>1,E29/모델!$C$36,1) -> 1 | F30: =IF(모델!$C$36>1,F29/모델!$C$36,1) -> 1 | G30: =IF(모델!$C$36>1,G29/모델!$C$36,1) -> 1 | H30: =IF(모델!$C$36>1,H29/모델!$C$36,1) -> 1 | I30: 균등: 토큰 하나가 특정 expert를 안 고를 확률 (1−k/E)의 N제곱. 실측 모드면 Expert 실측 시트 값
A31: expert당 토큰 수 (평균) | B31: =IF(모델!$C$36>1,B28*모델!$C$37/B29,B28) -> 16.000001 | C31: =IF(모델!$C$36>1,C28*모델!$C$37/C29,C28) -> 32 | D31: =IF(모델!$C$36>1,D28*모델!$C$37/D29,D28) -> 64 | E31: =IF(모델!$C$36>1,E28*모델!$C$37/E29,E28) -> 128 | F31: =IF(모델!$C$36>1,F28*모델!$C$37/F29,F28) -> 256 | G31: =IF(모델!$C$36>1,G28*모델!$C$37/G29,G28) -> 512 | H31: =IF(모델!$C$36>1,H28*모델!$C$37/H29,H28) -> 1024
A32: full.q_proj 연산량 (ops) | B32: =($D$5)*2*(B$28)*$B$5*$C$5 -> 36238786560 | C32: =($D$5)*2*(C$28)*$B$5*$C$5 -> 72477573120 | D32: =($D$5)*2*(D$28)*$B$5*$C$5 -> 144955146240 | E32: =($D$5)*2*(E$28)*$B$5*$C$5 -> 289910292480 | F32: =($D$5)*2*(F$28)*$B$5*$C$5 -> 579820584960 | G32: =($D$5)*2*(G$28)*$B$5*$C$5 -> 1159641169920 | H32: =($D$5)*2*(H$28)*$B$5*$C$5 -> 2319282339840
A33: full.q_proj DRAM 트래픽 (B) | B33: =($D$5)*MIN(($B$5*$C$5*$H$5)*MAX(1,ROUNDUP(((B$28)*$B$5*설정!$B$57)/설정!$B$61,0))+((B$28)*$B$5*설정!$B$57)+((B$28)*$C$5*설정!$B$57),($B$5*$C$5*$H$5)+((B$28)*$B$5*설정!$B$57)*MAX(1,ROUNDUP(($B$5*$C$5*$H$5)/설정!$B$61,0))+((B$28)*$C$5*설정!$B$57)) -> 83705856 | C33: =($D$5)*MIN(($B$5*$C$5*$H$5)*MAX(1,ROUNDUP(((C$28)*$B$5*설정!$B$57)/설정!$B$61,0))+((C$28)*$B$5*설정!$B$57)+((C$28)*$C$5*설정!$B$57),($B$5*$C$5*$H$5)+((C$28)*$B$5*설정!$B$57)*MAX(1,ROUNDUP(($B$5*$C$5*$H$5)/설정!$B$61,0))+((C$28)*$C$5*설정!$B$57)) -> 94420992 | D33: =($D$5)*MIN(($B$5*$C$5*$H$5)*MAX(1,ROUNDUP(((D$28)*$B$5*설정!$B$57)/설정!$B$61,0))+((D$28)*$B$5*설정!$B$57)+((D$28)*$C$5*설정!$B$57),($B$5*$C$5*$H$5)+((D$28)*$B$5*설정!$B$57)*MAX(1,ROUNDUP(($B$5*$C$5*$H$5)/설정!$B$61,0))+((D$28)*$C$5*설정!$B$57)) -> 115851264 | E33: =($D$5)*MIN(($B$5*$C$5*$H$5)*MAX(1,ROUNDUP(((E$28)*$B$5*설정!$B$57)/설정!$B$61,0))+((E$28)*$B$5*설정!$B$57)+((E$28)*$C$5*설정!$B$57),($B$5*$C$5*$H$5)+((E$28)*$B$5*설정!$B$57)*MAX(1,ROUNDUP(($B$5*$C$5*$H$5)/설정!$B$61,0))+((E$28)*$C$5*설정!$B$57)) -> 231702528 | F33: =($D$5)*MIN(($B$5*$C$5*$H$5)*MAX(1,ROUNDUP(((F$28)*$B$5*설정!$B$57)/설정!$B$61,0))+((F$28)*$B$5*설정!$B$57)+((F$28)*$C$5*설정!$B$57),($B$5*$C$5*$H$5)+((F$28)*$B$5*설정!$B$57)*MAX(1,ROUNDUP(($B$5*$C$5*$H$5)/설정!$B$61,0))+((F$28)*$C$5*설정!$B$57)) -> 456769536 | G33: =($D$5)*MIN(($B$5*$C$5*$H$5)*MAX(1,ROUNDUP(((G$28)*$B$5*설정!$B$57)/설정!$B$61,0))+((G$28)*$B$5*설정!$B$57)+((G$28)*$C$5*설정!$B$57),($B$5*$C$5*$H$5)+((G$28)*$B$5*설정!$B$57)*MAX(1,ROUNDUP(($B$5*$C$5*$H$5)/설정!$B$61,0))+((G$28)*$C$5*설정!$B$57)) -> 840548352 | H33: =($D$5)*MIN(($B$5*$C$5*$H$5)*MAX(1,ROUNDUP(((H$28)*$B$5*설정!$B$57)/설정!$B$61,0))+((H$28)*$B$5*설정!$B$57)+((H$28)*$C$5*설정!$B$57),($B$5*$C$5*$H$5)+((H$28)*$B$5*설정!$B$57)*MAX(1,ROUNDUP(($B$5*$C$5*$H$5)/설정!$B$61,0))+((H$28)*$C$5*설정!$B$57)) -> 1608105984
A34: full.q_proj 시간 (ms) | B34: =MAX(B32/$I$5,B33/설정!$B$60)*1000 -> 1.6412913 | C34: =MAX(C32/$I$5,C33/설정!$B$60)*1000 -> 3.0198989 | D34: =MAX(D32/$I$5,D33/설정!$B$60)*1000 -> 6.0397978 | E34: =MAX(E32/$I$5,E33/설정!$B$60)*1000 -> 12.079596 | F34: =MAX(F32/$I$5,F33/설정!$B$60)*1000 -> 24.159191 | G34: =MAX(G32/$I$5,G33/설정!$B$60)*1000 -> 48.318382 | H34: =MAX(H32/$I$5,H33/설정!$B$60)*1000 -> 96.636764
A35: full.k_proj 연산량 (ops) | B35: =($D$6)*2*(B$28)*$B$6*$C$6 -> 4529848320 | C35: =($D$6)*2*(C$28)*$B$6*$C$6 -> 9059696640 | D35: =($D$6)*2*(D$28)*$B$6*$C$6 -> 18119393280 | E35: =($D$6)*2*(E$28)*$B$6*$C$6 -> 36238786560 | F35: =($D$6)*2*(F$28)*$B$6*$C$6 -> 72477573120 | G35: =($D$6)*2*(G$28)*$B$6*$C$6 -> 144955146240 | H35: =($D$6)*2*(H$28)*$B$6*$C$6 -> 289910292480
A36: full.k_proj DRAM 트래픽 (B) | B36: =($D$6)*MIN(($B$6*$C$6*$H$6)*MAX(1,ROUNDUP(((B$28)*$B$6*설정!$B$57)/설정!$B$61,0))+((B$28)*$B$6*설정!$B$57)+((B$28)*$C$6*설정!$B$57),($B$6*$C$6*$H$6)+((B$28)*$B$6*설정!$B$57)*MAX(1,ROUNDUP(($B$6*$C$6*$H$6)/설정!$B$61,0))+((B$28)*$C$6*설정!$B$57)) -> 14333952 | C36: =($D$6)*MIN(($B$6*$C$6*$H$6)*MAX(1,ROUNDUP(((C$28)*$B$6*설정!$B$57)/설정!$B$61,0))+((C$28)*$B$6*설정!$B$57)+((C$28)*$C$6*설정!$B$57),($B$6*$C$6*$H$6)+((C$28)*$B$6*설정!$B$57)*MAX(1,ROUNDUP(($B$6*$C$6*$H$6)/설정!$B$61,0))+((C$28)*$C$6*설정!$B$57)) -> 19544064 | D36: =($D$6)*MIN(($B$6*$C$6*$H$6)*MAX(1,ROUNDUP(((D$28)*$B$6*설정!$B$57)/설정!$B$61,0))+((D$28)*$B$6*설정!$B$57)+((D$28)*$C$6*설정!$B$57),($B$6*$C$6*$H$6)+((D$28)*$B$6*설정!$B$57)*MAX(1,ROUNDUP(($B$6*$C$6*$H$6)/설정!$B$61,0))+((D$28)*$C$6*설정!$B$57)) -> 29964288 | E36: =($D$6)*MIN(($B$6*$C$6*$H$6)*MAX(1,ROUNDUP(((E$28)*$B$6*설정!$B$57)/설정!$B$61,0))+((E$28)*$B$6*설정!$B$57)+((E$28)*$C$6*설정!$B$57),($B$6*$C$6*$H$6)+((E$28)*$B$6*설정!$B$57)*MAX(1,ROUNDUP(($B$6*$C$6*$H$6)/설정!$B$61,0))+((E$28)*$C$6*설정!$B$57)) -> 50804736 | F36: =($D$6)*MIN(($B$6*$C$6*$H$6)*MAX(1,ROUNDUP(((F$28)*$B$6*설정!$B$57)/설정!$B$61,0))+((F$28)*$B$6*설정!$B$57)+((F$28)*$C$6*설정!$B$57),($B$6*$C$6*$H$6)+((F$28)*$B$6*설정!$B$57)*MAX(1,ROUNDUP(($B$6*$C$6*$H$6)/설정!$B$61,0))+((F$28)*$C$6*설정!$B$57)) -> 92485632 | G36: =($D$6)*MIN(($B$6*$C$6*$H$6)*MAX(1,ROUNDUP(((G$28)*$B$6*설정!$B$57)/설정!$B$61,0))+((G$28)*$B$6*설정!$B$57)+((G$28)*$C$6*설정!$B$57),($B$6*$C$6*$H$6)+((G$28)*$B$6*설정!$B$57)*MAX(1,ROUNDUP(($B$6*$C$6*$H$6)/설정!$B$61,0))+((G$28)*$C$6*설정!$B$57)) -> 175847424 | H36: =($D$6)*MIN(($B$6*$C$6*$H$6)*MAX(1,ROUNDUP(((H$28)*$B$6*설정!$B$57)/설정!$B$61,0))+((H$28)*$B$6*설정!$B$57)+((H$28)*$C$6*설정!$B$57),($B$6*$C$6*$H$6)+((H$28)*$B$6*설정!$B$57)*MAX(1,ROUNDUP(($B$6*$C$6*$H$6)/설정!$B$61,0))+((H$28)*$C$6*설정!$B$57)) -> 342571008
A37: full.k_proj 시간 (ms) | B37: =MAX(B35/$I$6,B36/설정!$B$60)*1000 -> 0.28105788 | C37: =MAX(C35/$I$6,C36/설정!$B$60)*1000 -> 0.38321694 | D37: =MAX(D35/$I$6,D36/설정!$B$60)*1000 -> 0.75497472 | E37: =MAX(E35/$I$6,E36/설정!$B$60)*1000 -> 1.5099494 | F37: =MAX(F35/$I$6,F36/설정!$B$60)*1000 -> 3.0198989 | G37: =MAX(G35/$I$6,G36/설정!$B$60)*1000 -> 6.0397978 | H37: =MAX(H35/$I$6,H36/설정!$B$60)*1000 -> 12.079596
A38: full.v_proj 연산량 (ops) | B38: =($D$7)*2*(B$28)*$B$7*$C$7 -> 4529848320 | C38: =($D$7)*2*(C$28)*$B$7*$C$7 -> 9059696640 | D38: =($D$7)*2*(D$28)*$B$7*$C$7 -> 18119393280 | E38: =($D$7)*2*(E$28)*$B$7*$C$7 -> 36238786560 | F38: =($D$7)*2*(F$28)*$B$7*$C$7 -> 72477573120 | G38: =($D$7)*2*(G$28)*$B$7*$C$7 -> 144955146240 | H38: =($D$7)*2*(H$28)*$B$7*$C$7 -> 289910292480
A39: full.v_proj DRAM 트래픽 (B) | B39: =($D$7)*MIN(($B$7*$C$7*$H$7)*MAX(1,ROUNDUP(((B$28)*$B$7*설정!$B$57)/설정!$B$61,0))+((B$28)*$B$7*설정!$B$57)+((B$28)*$C$7*설정!$B$57),($B$7*$C$7*$H$7)+((B$28)*$B$7*설정!$B$57)*MAX(1,ROUNDUP(($B$7*$C$7*$H$7)/설정!$B$61,0))+((B$28)*$C$7*설정!$B$57)) -> 14333952 | C39: =($D$7)*MIN(($B$7*$C$7*$H$7)*MAX(1,ROUNDUP(((C$28)*$B$7*설정!$B$57)/설정!$B$61,0))+((C$28)*$B$7*설정!$B$57)+((C$28)*$C$7*설정!$B$57),($B$7*$C$7*$H$7)+((C$28)*$B$7*설정!$B$57)*MAX(1,ROUNDUP(($B$7*$C$7*$H$7)/설정!$B$61,0))+((C$28)*$C$7*설정!$B$57)) -> 19544064 | D39: =($D$7)*MIN(($B$7*$C$7*$H$7)*MAX(1,ROUNDUP(((D$28)*$B$7*설정!$B$57)/설정!$B$61,0))+((D$28)*$B$7*설정!$B$57)+((D$28)*$C$7*설정!$B$57),($B$7*$C$7*$H$7)+((D$28)*$B$7*설정!$B$57)*MAX(1,ROUNDUP(($B$7*$C$7*$H$7)/설정!$B$61,0))+((D$28)*$C$7*설정!$B$57)) -> 29964288 | E39: =($D$7)*MIN(($B$7*$C$7*$H$7)*MAX(1,ROUNDUP(((E$28)*$B$7*설정!$B$57)/설정!$B$61,0))+((E$28)*$B$7*설정!$B$57)+((E$28)*$C$7*설정!$B$57),($B$7*$C$7*$H$7)+((E$28)*$B$7*설정!$B$57)*MAX(1,ROUNDUP(($B$7*$C$7*$H$7)/설정!$B$61,0))+((E$28)*$C$7*설정!$B$57)) -> 50804736 | F39: =($D$7)*MIN(($B$7*$C$7*$H$7)*MAX(1,ROUNDUP(((F$28)*$B$7*설정!$B$57)/설정!$B$61,0))+((F$28)*$B$7*설정!$B$57)+((F$28)*$C$7*설정!$B$57),($B$7*$C$7*$H$7)+((F$28)*$B$7*설정!$B$57)*MAX(1,ROUNDUP(($B$7*$C$7*$H$7)/설정!$B$61,0))+((F$28)*$C$7*설정!$B$57)) -> 92485632 | G39: =($D$7)*MIN(($B$7*$C$7*$H$7)*MAX(1,ROUNDUP(((G$28)*$B$7*설정!$B$57)/설정!$B$61,0))+((G$28)*$B$7*설정!$B$57)+((G$28)*$C$7*설정!$B$57),($B$7*$C$7*$H$7)+((G$28)*$B$7*설정!$B$57)*MAX(1,ROUNDUP(($B$7*$C$7*$H$7)/설정!$B$61,0))+((G$28)*$C$7*설정!$B$57)) -> 175847424 | H39: =($D$7)*MIN(($B$7*$C$7*$H$7)*MAX(1,ROUNDUP(((H$28)*$B$7*설정!$B$57)/설정!$B$61,0))+((H$28)*$B$7*설정!$B$57)+((H$28)*$C$7*설정!$B$57),($B$7*$C$7*$H$7)+((H$28)*$B$7*설정!$B$57)*MAX(1,ROUNDUP(($B$7*$C$7*$H$7)/설정!$B$61,0))+((H$28)*$C$7*설정!$B$57)) -> 342571008
A40: full.v_proj 시간 (ms) | B40: =MAX(B38/$I$7,B39/설정!$B$60)*1000 -> 0.28105788 | C40: =MAX(C38/$I$7,C39/설정!$B$60)*1000 -> 0.38321694 | D40: =MAX(D38/$I$7,D39/설정!$B$60)*1000 -> 0.75497472 | E40: =MAX(E38/$I$7,E39/설정!$B$60)*1000 -> 1.5099494 | F40: =MAX(F38/$I$7,F39/설정!$B$60)*1000 -> 3.0198989 | G40: =MAX(G38/$I$7,G39/설정!$B$60)*1000 -> 6.0397978 | H40: =MAX(H38/$I$7,H39/설정!$B$60)*1000 -> 12.079596
A41: full.o_proj 연산량 (ops) | B41: =($D$8)*2*(B$28)*$B$8*$C$8 -> 36238786560 | C41: =($D$8)*2*(C$28)*$B$8*$C$8 -> 72477573120 | D41: =($D$8)*2*(D$28)*$B$8*$C$8 -> 144955146240 | E41: =($D$8)*2*(E$28)*$B$8*$C$8 -> 289910292480 | F41: =($D$8)*2*(F$28)*$B$8*$C$8 -> 579820584960 | G41: =($D$8)*2*(G$28)*$B$8*$C$8 -> 1159641169920 | H41: =($D$8)*2*(H$28)*$B$8*$C$8 -> 2319282339840
